{
 "cells": [
  {
   "cell_type": "code",
   "execution_count": 20,
   "metadata": {
    "scrolled": true
   },
   "outputs": [
    {
     "name": "stdout",
     "output_type": "stream",
     "text": [
      "········\n",
      " * Serving Flask app \"Dash Datatable\" (lazy loading)\n",
      " * Environment: production\n",
      "   WARNING: This is a development server. Do not use it in a production deployment.\n",
      "   Use a production WSGI server instead.\n",
      " * Debug mode: off\n"
     ]
    },
    {
     "name": "stderr",
     "output_type": "stream",
     "text": [
      " * Running on http://127.0.0.1:8050/ (Press CTRL+C to quit)\n",
      "127.0.0.1 - - [17/Oct/2022 03:28:32] \"\u001b[37mGET / HTTP/1.1\u001b[0m\" 200 -\n",
      "127.0.0.1 - - [17/Oct/2022 03:28:32] \"\u001b[37mGET /_dash-component-suites/dash_renderer/react@16.v1_3_0m1588250875.13.0.min.js HTTP/1.1\u001b[0m\" 200 -\n",
      "127.0.0.1 - - [17/Oct/2022 03:28:32] \"\u001b[37mGET /_dash-component-suites/dash_renderer/polyfill@7.v1_3_0m1588250875.8.7.min.js HTTP/1.1\u001b[0m\" 200 -\n",
      "127.0.0.1 - - [17/Oct/2022 03:28:32] \"\u001b[37mGET /_dash-component-suites/dash_renderer/prop-types@15.v1_3_0m1588250875.7.2.min.js HTTP/1.1\u001b[0m\" 200 -\n",
      "127.0.0.1 - - [17/Oct/2022 03:28:32] \"\u001b[37mGET /_dash-component-suites/dash_renderer/react-dom@16.v1_3_0m1588250875.13.0.min.js HTTP/1.1\u001b[0m\" 200 -\n",
      "127.0.0.1 - - [17/Oct/2022 03:28:32] \"\u001b[37mGET /_dash-component-suites/dash_core_components/dash_core_components.v1_9_0m1588250878.min.js HTTP/1.1\u001b[0m\" 200 -\n",
      "127.0.0.1 - - [17/Oct/2022 03:28:32] \"\u001b[37mGET /_dash-component-suites/dash_core_components/dash_core_components-shared.v1_9_0m1588250878.js HTTP/1.1\u001b[0m\" 200 -\n",
      "127.0.0.1 - - [17/Oct/2022 03:28:32] \"\u001b[37mGET /_dash-component-suites/dash_table/bundle.v4_6_2m1585840851.js HTTP/1.1\u001b[0m\" 200 -\n",
      "127.0.0.1 - - [17/Oct/2022 03:28:32] \"\u001b[37mGET /_dash-component-suites/dash_html_components/dash_html_components.v1_0_3m1585840840.min.js HTTP/1.1\u001b[0m\" 200 -\n",
      "127.0.0.1 - - [17/Oct/2022 03:28:32] \"\u001b[37mGET /_dash-component-suites/dash_renderer/dash_renderer.v1_3_0m1588250875.min.js HTTP/1.1\u001b[0m\" 200 -\n",
      "127.0.0.1 - - [17/Oct/2022 03:28:32] \"\u001b[37mGET /_dash-component-suites/dash_leaflet/dash_leaflet.v0_0_9m1588250815.min.js HTTP/1.1\u001b[0m\" 200 -\n",
      "127.0.0.1 - - [17/Oct/2022 03:28:32] \"\u001b[37mGET /_dash-dependencies HTTP/1.1\u001b[0m\" 200 -\n",
      "127.0.0.1 - - [17/Oct/2022 03:28:32] \"\u001b[37mGET /_dash-layout HTTP/1.1\u001b[0m\" 200 -\n"
     ]
    },
    {
     "name": "stdout",
     "output_type": "stream",
     "text": [
      "Exception on /_dash-update-component [POST]\n",
      "Traceback (most recent call last):\n",
      "  File \"/usr/local/anaconda/lib/python3.6/site-packages/flask/app.py\", line 2446, in wsgi_app\n",
      "    response = self.full_dispatch_request()\n",
      "  File \"/usr/local/anaconda/lib/python3.6/site-packages/flask/app.py\", line 1951, in full_dispatch_request\n",
      "    rv = self.handle_user_exception(e)\n",
      "  File \"/usr/local/anaconda/lib/python3.6/site-packages/flask/app.py\", line 1820, in handle_user_exception\n",
      "    reraise(exc_type, exc_value, tb)\n",
      "  File \"/usr/local/anaconda/lib/python3.6/site-packages/flask/_compat.py\", line 39, in reraise\n",
      "    raise value\n",
      "  File \"/usr/local/anaconda/lib/python3.6/site-packages/flask/app.py\", line 1949, in full_dispatch_request\n",
      "    rv = self.dispatch_request()\n",
      "  File \"/usr/local/anaconda/lib/python3.6/site-packages/flask/app.py\", line 1935, in dispatch_request\n",
      "    return self.view_functions[rule.endpoint](**req.view_args)\n",
      "  File \"/usr/local/anaconda/lib/python3.6/site-packages/dash/dash.py\", line 1407, in dispatch\n",
      "    response.set_data(self.callback_map[output][\"callback\"](*args))\n",
      "  File \"/usr/local/anaconda/lib/python3.6/site-packages/dash/dash.py\", line 1294, in add_context\n",
      "    output_value = func(*args, **kwargs)  # %% callback invoked %%\n",
      "  File \"<ipython-input-20-660bae554010>\", line 193, in update_map\n",
      "    dl.Map(style={'width': '1000px', 'height': '500px'}, center=[dff.iloc[0,13], dff.iloc[0,14]], zoom=10, children=[\n",
      "  File \"/usr/local/anaconda/lib/python3.6/site-packages/pandas/core/indexing.py\", line 1418, in __getitem__\n",
      "    return self._getitem_tuple(key)\n",
      "  File \"/usr/local/anaconda/lib/python3.6/site-packages/pandas/core/indexing.py\", line 2092, in _getitem_tuple\n",
      "    self._has_valid_tuple(tup)\n",
      "  File \"/usr/local/anaconda/lib/python3.6/site-packages/pandas/core/indexing.py\", line 235, in _has_valid_tuple\n",
      "    self._validate_key(k, i)\n",
      "  File \"/usr/local/anaconda/lib/python3.6/site-packages/pandas/core/indexing.py\", line 2014, in _validate_key\n",
      "    self._validate_integer(key, axis)\n",
      "  File \"/usr/local/anaconda/lib/python3.6/site-packages/pandas/core/indexing.py\", line 2088, in _validate_integer\n",
      "    raise IndexError(\"single positional indexer is out-of-bounds\")\n",
      "IndexError: single positional indexer is out-of-bounds\n",
      "Exception on /_dash-update-component [POST]\n",
      "Traceback (most recent call last):\n",
      "  File \"/usr/local/anaconda/lib/python3.6/site-packages/flask/app.py\", line 2446, in wsgi_app\n",
      "    response = self.full_dispatch_request()\n",
      "  File \"/usr/local/anaconda/lib/python3.6/site-packages/flask/app.py\", line 1951, in full_dispatch_request\n",
      "    rv = self.handle_user_exception(e)\n",
      "  File \"/usr/local/anaconda/lib/python3.6/site-packages/flask/app.py\", line 1820, in handle_user_exception\n",
      "    reraise(exc_type, exc_value, tb)\n",
      "  File \"/usr/local/anaconda/lib/python3.6/site-packages/flask/_compat.py\", line 39, in reraise\n",
      "    raise value\n",
      "  File \"/usr/local/anaconda/lib/python3.6/site-packages/flask/app.py\", line 1949, in full_dispatch_request\n",
      "    rv = self.dispatch_request()\n",
      "  File \"/usr/local/anaconda/lib/python3.6/site-packages/flask/app.py\", line 1935, in dispatch_request\n",
      "    return self.view_functions[rule.endpoint](**req.view_args)\n",
      "  File \"/usr/local/anaconda/lib/python3.6/site-packages/dash/dash.py\", line 1407, in dispatch\n",
      "    response.set_data(self.callback_map[output][\"callback\"](*args))\n",
      "  File \"/usr/local/anaconda/lib/python3.6/site-packages/dash/dash.py\", line 1294, in add_context\n",
      "    output_value = func(*args, **kwargs)  # %% callback invoked %%\n",
      "  File \"<ipython-input-20-660bae554010>\", line 193, in update_map\n",
      "    dl.Map(style={'width': '1000px', 'height': '500px'}, center=[dff.iloc[0,13], dff.iloc[0,14]], zoom=10, children=[\n",
      "  File \"/usr/local/anaconda/lib/python3.6/site-packages/pandas/core/indexing.py\", line 1418, in __getitem__\n",
      "    return self._getitem_tuple(key)\n",
      "  File \"/usr/local/anaconda/lib/python3.6/site-packages/pandas/core/indexing.py\", line 2092, in _getitem_tuple\n",
      "    self._has_valid_tuple(tup)\n",
      "  File \"/usr/local/anaconda/lib/python3.6/site-packages/pandas/core/indexing.py\", line 235, in _has_valid_tuple\n",
      "    self._validate_key(k, i)\n",
      "  File \"/usr/local/anaconda/lib/python3.6/site-packages/pandas/core/indexing.py\", line 2014, in _validate_key\n",
      "    self._validate_integer(key, axis)\n",
      "  File \"/usr/local/anaconda/lib/python3.6/site-packages/pandas/core/indexing.py\", line 2088, in _validate_integer\n",
      "    raise IndexError(\"single positional indexer is out-of-bounds\")\n",
      "IndexError: single positional indexer is out-of-bounds\n",
      "Exception on /_dash-update-component [POST]\n",
      "Traceback (most recent call last):\n",
      "  File \"/usr/local/anaconda/lib/python3.6/site-packages/flask/app.py\", line 2446, in wsgi_app\n",
      "    response = self.full_dispatch_request()\n",
      "  File \"/usr/local/anaconda/lib/python3.6/site-packages/flask/app.py\", line 1951, in full_dispatch_request\n",
      "    rv = self.handle_user_exception(e)\n",
      "  File \"/usr/local/anaconda/lib/python3.6/site-packages/flask/app.py\", line 1820, in handle_user_exception\n",
      "    reraise(exc_type, exc_value, tb)\n",
      "  File \"/usr/local/anaconda/lib/python3.6/site-packages/flask/_compat.py\", line 39, in reraise\n",
      "    raise value\n",
      "  File \"/usr/local/anaconda/lib/python3.6/site-packages/flask/app.py\", line 1949, in full_dispatch_request\n",
      "    rv = self.dispatch_request()\n",
      "  File \"/usr/local/anaconda/lib/python3.6/site-packages/flask/app.py\", line 1935, in dispatch_request\n",
      "    return self.view_functions[rule.endpoint](**req.view_args)\n",
      "  File \"/usr/local/anaconda/lib/python3.6/site-packages/dash/dash.py\", line 1407, in dispatch\n",
      "    response.set_data(self.callback_map[output][\"callback\"](*args))\n",
      "  File \"/usr/local/anaconda/lib/python3.6/site-packages/dash/dash.py\", line 1294, in add_context\n",
      "    output_value = func(*args, **kwargs)  # %% callback invoked %%\n",
      "  File \"<ipython-input-20-660bae554010>\", line 193, in update_map\n",
      "    dl.Map(style={'width': '1000px', 'height': '500px'}, center=[dff.iloc[0,13], dff.iloc[0,14]], zoom=10, children=[\n",
      "  File \"/usr/local/anaconda/lib/python3.6/site-packages/pandas/core/indexing.py\", line 1418, in __getitem__\n",
      "    return self._getitem_tuple(key)\n",
      "  File \"/usr/local/anaconda/lib/python3.6/site-packages/pandas/core/indexing.py\", line 2092, in _getitem_tuple\n",
      "    self._has_valid_tuple(tup)\n",
      "  File \"/usr/local/anaconda/lib/python3.6/site-packages/pandas/core/indexing.py\", line 235, in _has_valid_tuple\n",
      "    self._validate_key(k, i)\n",
      "  File \"/usr/local/anaconda/lib/python3.6/site-packages/pandas/core/indexing.py\", line 2014, in _validate_key\n",
      "    self._validate_integer(key, axis)\n",
      "  File \"/usr/local/anaconda/lib/python3.6/site-packages/pandas/core/indexing.py\", line 2088, in _validate_integer\n",
      "    raise IndexError(\"single positional indexer is out-of-bounds\")\n",
      "IndexError: single positional indexer is out-of-bounds\n",
      "Exception on /_dash-update-component [POST]\n",
      "Traceback (most recent call last):\n",
      "  File \"/usr/local/anaconda/lib/python3.6/site-packages/flask/app.py\", line 2446, in wsgi_app\n",
      "    response = self.full_dispatch_request()\n",
      "  File \"/usr/local/anaconda/lib/python3.6/site-packages/flask/app.py\", line 1951, in full_dispatch_request\n",
      "    rv = self.handle_user_exception(e)\n",
      "  File \"/usr/local/anaconda/lib/python3.6/site-packages/flask/app.py\", line 1820, in handle_user_exception\n",
      "    reraise(exc_type, exc_value, tb)\n",
      "  File \"/usr/local/anaconda/lib/python3.6/site-packages/flask/_compat.py\", line 39, in reraise\n",
      "    raise value\n",
      "  File \"/usr/local/anaconda/lib/python3.6/site-packages/flask/app.py\", line 1949, in full_dispatch_request\n",
      "    rv = self.dispatch_request()\n",
      "  File \"/usr/local/anaconda/lib/python3.6/site-packages/flask/app.py\", line 1935, in dispatch_request\n",
      "    return self.view_functions[rule.endpoint](**req.view_args)\n",
      "  File \"/usr/local/anaconda/lib/python3.6/site-packages/dash/dash.py\", line 1407, in dispatch\n",
      "    response.set_data(self.callback_map[output][\"callback\"](*args))\n",
      "  File \"/usr/local/anaconda/lib/python3.6/site-packages/dash/dash.py\", line 1294, in add_context\n",
      "    output_value = func(*args, **kwargs)  # %% callback invoked %%\n",
      "  File \"<ipython-input-20-660bae554010>\", line 193, in update_map\n",
      "    dl.Map(style={'width': '1000px', 'height': '500px'}, center=[dff.iloc[0,13], dff.iloc[0,14]], zoom=10, children=[\n",
      "  File \"/usr/local/anaconda/lib/python3.6/site-packages/pandas/core/indexing.py\", line 1418, in __getitem__\n",
      "    return self._getitem_tuple(key)\n",
      "  File \"/usr/local/anaconda/lib/python3.6/site-packages/pandas/core/indexing.py\", line 2092, in _getitem_tuple\n",
      "    self._has_valid_tuple(tup)\n",
      "  File \"/usr/local/anaconda/lib/python3.6/site-packages/pandas/core/indexing.py\", line 235, in _has_valid_tuple\n",
      "    self._validate_key(k, i)\n",
      "  File \"/usr/local/anaconda/lib/python3.6/site-packages/pandas/core/indexing.py\", line 2014, in _validate_key\n",
      "    self._validate_integer(key, axis)\n",
      "  File \"/usr/local/anaconda/lib/python3.6/site-packages/pandas/core/indexing.py\", line 2088, in _validate_integer\n",
      "    raise IndexError(\"single positional indexer is out-of-bounds\")\n",
      "IndexError: single positional indexer is out-of-bounds\n"
     ]
    },
    {
     "name": "stdout",
     "output_type": "stream",
     "text": [
      "Exception on /_dash-update-component [POST]\n",
      "Traceback (most recent call last):\n",
      "  File \"/usr/local/anaconda/lib/python3.6/site-packages/flask/app.py\", line 2446, in wsgi_app\n",
      "    response = self.full_dispatch_request()\n",
      "  File \"/usr/local/anaconda/lib/python3.6/site-packages/flask/app.py\", line 1951, in full_dispatch_request\n",
      "    rv = self.handle_user_exception(e)\n",
      "  File \"/usr/local/anaconda/lib/python3.6/site-packages/flask/app.py\", line 1820, in handle_user_exception\n",
      "    reraise(exc_type, exc_value, tb)\n",
      "  File \"/usr/local/anaconda/lib/python3.6/site-packages/flask/_compat.py\", line 39, in reraise\n",
      "    raise value\n",
      "  File \"/usr/local/anaconda/lib/python3.6/site-packages/flask/app.py\", line 1949, in full_dispatch_request\n",
      "    rv = self.dispatch_request()\n",
      "  File \"/usr/local/anaconda/lib/python3.6/site-packages/flask/app.py\", line 1935, in dispatch_request\n",
      "    return self.view_functions[rule.endpoint](**req.view_args)\n",
      "  File \"/usr/local/anaconda/lib/python3.6/site-packages/dash/dash.py\", line 1407, in dispatch\n",
      "    response.set_data(self.callback_map[output][\"callback\"](*args))\n",
      "  File \"/usr/local/anaconda/lib/python3.6/site-packages/dash/dash.py\", line 1294, in add_context\n",
      "    output_value = func(*args, **kwargs)  # %% callback invoked %%\n",
      "  File \"<ipython-input-20-660bae554010>\", line 193, in update_map\n",
      "    dl.Map(style={'width': '1000px', 'height': '500px'}, center=[dff.iloc[0,13], dff.iloc[0,14]], zoom=10, children=[\n",
      "  File \"/usr/local/anaconda/lib/python3.6/site-packages/pandas/core/indexing.py\", line 1418, in __getitem__\n",
      "    return self._getitem_tuple(key)\n",
      "  File \"/usr/local/anaconda/lib/python3.6/site-packages/pandas/core/indexing.py\", line 2092, in _getitem_tuple\n",
      "    self._has_valid_tuple(tup)\n",
      "  File \"/usr/local/anaconda/lib/python3.6/site-packages/pandas/core/indexing.py\", line 235, in _has_valid_tuple\n",
      "    self._validate_key(k, i)\n",
      "  File \"/usr/local/anaconda/lib/python3.6/site-packages/pandas/core/indexing.py\", line 2014, in _validate_key\n",
      "    self._validate_integer(key, axis)\n",
      "  File \"/usr/local/anaconda/lib/python3.6/site-packages/pandas/core/indexing.py\", line 2088, in _validate_integer\n",
      "    raise IndexError(\"single positional indexer is out-of-bounds\")\n",
      "IndexError: single positional indexer is out-of-bounds\n",
      "Exception on /_dash-update-component [POST]\n",
      "Traceback (most recent call last):\n",
      "  File \"/usr/local/anaconda/lib/python3.6/site-packages/flask/app.py\", line 2446, in wsgi_app\n",
      "    response = self.full_dispatch_request()\n",
      "  File \"/usr/local/anaconda/lib/python3.6/site-packages/flask/app.py\", line 1951, in full_dispatch_request\n",
      "    rv = self.handle_user_exception(e)\n",
      "  File \"/usr/local/anaconda/lib/python3.6/site-packages/flask/app.py\", line 1820, in handle_user_exception\n",
      "    reraise(exc_type, exc_value, tb)\n",
      "  File \"/usr/local/anaconda/lib/python3.6/site-packages/flask/_compat.py\", line 39, in reraise\n",
      "    raise value\n",
      "  File \"/usr/local/anaconda/lib/python3.6/site-packages/flask/app.py\", line 1949, in full_dispatch_request\n",
      "    rv = self.dispatch_request()\n",
      "  File \"/usr/local/anaconda/lib/python3.6/site-packages/flask/app.py\", line 1935, in dispatch_request\n",
      "    return self.view_functions[rule.endpoint](**req.view_args)\n",
      "  File \"/usr/local/anaconda/lib/python3.6/site-packages/dash/dash.py\", line 1407, in dispatch\n",
      "    response.set_data(self.callback_map[output][\"callback\"](*args))\n",
      "  File \"/usr/local/anaconda/lib/python3.6/site-packages/dash/dash.py\", line 1294, in add_context\n",
      "    output_value = func(*args, **kwargs)  # %% callback invoked %%\n",
      "  File \"<ipython-input-20-660bae554010>\", line 193, in update_map\n",
      "    dl.Map(style={'width': '1000px', 'height': '500px'}, center=[dff.iloc[0,13], dff.iloc[0,14]], zoom=10, children=[\n",
      "  File \"/usr/local/anaconda/lib/python3.6/site-packages/pandas/core/indexing.py\", line 1418, in __getitem__\n",
      "    return self._getitem_tuple(key)\n",
      "  File \"/usr/local/anaconda/lib/python3.6/site-packages/pandas/core/indexing.py\", line 2092, in _getitem_tuple\n",
      "    self._has_valid_tuple(tup)\n",
      "  File \"/usr/local/anaconda/lib/python3.6/site-packages/pandas/core/indexing.py\", line 235, in _has_valid_tuple\n",
      "    self._validate_key(k, i)\n",
      "  File \"/usr/local/anaconda/lib/python3.6/site-packages/pandas/core/indexing.py\", line 2014, in _validate_key\n",
      "    self._validate_integer(key, axis)\n",
      "  File \"/usr/local/anaconda/lib/python3.6/site-packages/pandas/core/indexing.py\", line 2088, in _validate_integer\n",
      "    raise IndexError(\"single positional indexer is out-of-bounds\")\n",
      "IndexError: single positional indexer is out-of-bounds\n",
      "Exception on /_dash-update-component [POST]\n",
      "Traceback (most recent call last):\n",
      "  File \"/usr/local/anaconda/lib/python3.6/site-packages/flask/app.py\", line 2446, in wsgi_app\n",
      "    response = self.full_dispatch_request()\n",
      "  File \"/usr/local/anaconda/lib/python3.6/site-packages/flask/app.py\", line 1951, in full_dispatch_request\n",
      "    rv = self.handle_user_exception(e)\n",
      "  File \"/usr/local/anaconda/lib/python3.6/site-packages/flask/app.py\", line 1820, in handle_user_exception\n",
      "    reraise(exc_type, exc_value, tb)\n",
      "  File \"/usr/local/anaconda/lib/python3.6/site-packages/flask/_compat.py\", line 39, in reraise\n",
      "    raise value\n",
      "  File \"/usr/local/anaconda/lib/python3.6/site-packages/flask/app.py\", line 1949, in full_dispatch_request\n",
      "    rv = self.dispatch_request()\n",
      "  File \"/usr/local/anaconda/lib/python3.6/site-packages/flask/app.py\", line 1935, in dispatch_request\n",
      "    return self.view_functions[rule.endpoint](**req.view_args)\n",
      "  File \"/usr/local/anaconda/lib/python3.6/site-packages/dash/dash.py\", line 1407, in dispatch\n",
      "    response.set_data(self.callback_map[output][\"callback\"](*args))\n",
      "  File \"/usr/local/anaconda/lib/python3.6/site-packages/dash/dash.py\", line 1294, in add_context\n",
      "    output_value = func(*args, **kwargs)  # %% callback invoked %%\n",
      "  File \"<ipython-input-20-660bae554010>\", line 193, in update_map\n",
      "    dl.Map(style={'width': '1000px', 'height': '500px'}, center=[dff.iloc[0,13], dff.iloc[0,14]], zoom=10, children=[\n",
      "  File \"/usr/local/anaconda/lib/python3.6/site-packages/pandas/core/indexing.py\", line 1418, in __getitem__\n",
      "    return self._getitem_tuple(key)\n",
      "  File \"/usr/local/anaconda/lib/python3.6/site-packages/pandas/core/indexing.py\", line 2092, in _getitem_tuple\n",
      "    self._has_valid_tuple(tup)\n",
      "  File \"/usr/local/anaconda/lib/python3.6/site-packages/pandas/core/indexing.py\", line 235, in _has_valid_tuple\n",
      "    self._validate_key(k, i)\n",
      "  File \"/usr/local/anaconda/lib/python3.6/site-packages/pandas/core/indexing.py\", line 2014, in _validate_key\n",
      "    self._validate_integer(key, axis)\n",
      "  File \"/usr/local/anaconda/lib/python3.6/site-packages/pandas/core/indexing.py\", line 2088, in _validate_integer\n",
      "    raise IndexError(\"single positional indexer is out-of-bounds\")\n",
      "IndexError: single positional indexer is out-of-bounds\n",
      "Exception on /_dash-update-component [POST]\n",
      "Traceback (most recent call last):\n",
      "  File \"/usr/local/anaconda/lib/python3.6/site-packages/flask/app.py\", line 2446, in wsgi_app\n",
      "    response = self.full_dispatch_request()\n",
      "  File \"/usr/local/anaconda/lib/python3.6/site-packages/flask/app.py\", line 1951, in full_dispatch_request\n",
      "    rv = self.handle_user_exception(e)\n",
      "  File \"/usr/local/anaconda/lib/python3.6/site-packages/flask/app.py\", line 1820, in handle_user_exception\n",
      "    reraise(exc_type, exc_value, tb)\n",
      "  File \"/usr/local/anaconda/lib/python3.6/site-packages/flask/_compat.py\", line 39, in reraise\n",
      "    raise value\n",
      "  File \"/usr/local/anaconda/lib/python3.6/site-packages/flask/app.py\", line 1949, in full_dispatch_request\n",
      "    rv = self.dispatch_request()\n",
      "  File \"/usr/local/anaconda/lib/python3.6/site-packages/flask/app.py\", line 1935, in dispatch_request\n",
      "    return self.view_functions[rule.endpoint](**req.view_args)\n",
      "  File \"/usr/local/anaconda/lib/python3.6/site-packages/dash/dash.py\", line 1407, in dispatch\n",
      "    response.set_data(self.callback_map[output][\"callback\"](*args))\n",
      "  File \"/usr/local/anaconda/lib/python3.6/site-packages/dash/dash.py\", line 1294, in add_context\n",
      "    output_value = func(*args, **kwargs)  # %% callback invoked %%\n",
      "  File \"<ipython-input-20-660bae554010>\", line 193, in update_map\n",
      "    dl.Map(style={'width': '1000px', 'height': '500px'}, center=[dff.iloc[0,13], dff.iloc[0,14]], zoom=10, children=[\n",
      "  File \"/usr/local/anaconda/lib/python3.6/site-packages/pandas/core/indexing.py\", line 1418, in __getitem__\n",
      "    return self._getitem_tuple(key)\n",
      "  File \"/usr/local/anaconda/lib/python3.6/site-packages/pandas/core/indexing.py\", line 2092, in _getitem_tuple\n",
      "    self._has_valid_tuple(tup)\n",
      "  File \"/usr/local/anaconda/lib/python3.6/site-packages/pandas/core/indexing.py\", line 235, in _has_valid_tuple\n",
      "    self._validate_key(k, i)\n",
      "  File \"/usr/local/anaconda/lib/python3.6/site-packages/pandas/core/indexing.py\", line 2014, in _validate_key\n",
      "    self._validate_integer(key, axis)\n",
      "  File \"/usr/local/anaconda/lib/python3.6/site-packages/pandas/core/indexing.py\", line 2088, in _validate_integer\n",
      "    raise IndexError(\"single positional indexer is out-of-bounds\")\n",
      "IndexError: single positional indexer is out-of-bounds\n"
     ]
    },
    {
     "name": "stderr",
     "output_type": "stream",
     "text": [
      "127.0.0.1 - - [17/Oct/2022 03:28:33] \"\u001b[37mPOST /_dash-update-component HTTP/1.1\u001b[0m\" 200 -\n"
     ]
    },
    {
     "name": "stdout",
     "output_type": "stream",
     "text": [
      "Exception on /_dash-update-component [POST]\n",
      "Traceback (most recent call last):\n",
      "  File \"/usr/local/anaconda/lib/python3.6/site-packages/pandas/core/indexes/base.py\", line 2897, in get_loc\n",
      "    return self._engine.get_loc(key)\n",
      "  File \"pandas/_libs/index.pyx\", line 107, in pandas._libs.index.IndexEngine.get_loc\n",
      "  File \"pandas/_libs/index.pyx\", line 131, in pandas._libs.index.IndexEngine.get_loc\n",
      "  File \"pandas/_libs/hashtable_class_helper.pxi\", line 1607, in pandas._libs.hashtable.PyObjectHashTable.get_item\n",
      "  File \"pandas/_libs/hashtable_class_helper.pxi\", line 1614, in pandas._libs.hashtable.PyObjectHashTable.get_item\n",
      "KeyError: 'breed'\n",
      "\n",
      "During handling of the above exception, another exception occurred:\n",
      "\n",
      "Traceback (most recent call last):\n",
      "  File \"/usr/local/anaconda/lib/python3.6/site-packages/flask/app.py\", line 2446, in wsgi_app\n",
      "    response = self.full_dispatch_request()\n",
      "  File \"/usr/local/anaconda/lib/python3.6/site-packages/flask/app.py\", line 1951, in full_dispatch_request\n",
      "    rv = self.handle_user_exception(e)\n",
      "  File \"/usr/local/anaconda/lib/python3.6/site-packages/flask/app.py\", line 1820, in handle_user_exception\n",
      "    reraise(exc_type, exc_value, tb)\n",
      "  File \"/usr/local/anaconda/lib/python3.6/site-packages/flask/_compat.py\", line 39, in reraise\n",
      "    raise value\n",
      "  File \"/usr/local/anaconda/lib/python3.6/site-packages/flask/app.py\", line 1949, in full_dispatch_request\n",
      "    rv = self.dispatch_request()\n",
      "  File \"/usr/local/anaconda/lib/python3.6/site-packages/flask/app.py\", line 1935, in dispatch_request\n",
      "    return self.view_functions[rule.endpoint](**req.view_args)\n",
      "  File \"/usr/local/anaconda/lib/python3.6/site-packages/dash/dash.py\", line 1407, in dispatch\n",
      "    response.set_data(self.callback_map[output][\"callback\"](*args))\n",
      "  File \"/usr/local/anaconda/lib/python3.6/site-packages/dash/dash.py\", line 1294, in add_context\n",
      "    output_value = func(*args, **kwargs)  # %% callback invoked %%\n",
      "  File \"<ipython-input-20-660bae554010>\", line 175, in update_graphs\n",
      "    a = dff['breed'].unique() #Have to instantiate unique breeds before sorting so pie graph values align with breed\n",
      "  File \"/usr/local/anaconda/lib/python3.6/site-packages/pandas/core/frame.py\", line 2980, in __getitem__\n",
      "    indexer = self.columns.get_loc(key)\n",
      "  File \"/usr/local/anaconda/lib/python3.6/site-packages/pandas/core/indexes/base.py\", line 2899, in get_loc\n",
      "    return self._engine.get_loc(self._maybe_cast_indexer(key))\n",
      "  File \"pandas/_libs/index.pyx\", line 107, in pandas._libs.index.IndexEngine.get_loc\n",
      "  File \"pandas/_libs/index.pyx\", line 131, in pandas._libs.index.IndexEngine.get_loc\n",
      "  File \"pandas/_libs/hashtable_class_helper.pxi\", line 1607, in pandas._libs.hashtable.PyObjectHashTable.get_item\n",
      "  File \"pandas/_libs/hashtable_class_helper.pxi\", line 1614, in pandas._libs.hashtable.PyObjectHashTable.get_item\n",
      "KeyError: 'breed'Exception on /_dash-update-component [POST]\n",
      "Traceback (most recent call last):\n",
      "  File \"/usr/local/anaconda/lib/python3.6/site-packages/flask/app.py\", line 2446, in wsgi_app\n",
      "    response = self.full_dispatch_request()\n",
      "  File \"/usr/local/anaconda/lib/python3.6/site-packages/flask/app.py\", line 1951, in full_dispatch_request\n",
      "    rv = self.handle_user_exception(e)\n",
      "  File \"/usr/local/anaconda/lib/python3.6/site-packages/flask/app.py\", line 1820, in handle_user_exception\n",
      "    reraise(exc_type, exc_value, tb)\n",
      "  File \"/usr/local/anaconda/lib/python3.6/site-packages/flask/_compat.py\", line 39, in reraise\n",
      "    raise value\n",
      "  File \"/usr/local/anaconda/lib/python3.6/site-packages/flask/app.py\", line 1949, in full_dispatch_request\n",
      "    rv = self.dispatch_request()\n",
      "  File \"/usr/local/anaconda/lib/python3.6/site-packages/flask/app.py\", line 1935, in dispatch_request\n",
      "    return self.view_functions[rule.endpoint](**req.view_args)\n",
      "  File \"/usr/local/anaconda/lib/python3.6/site-packages/dash/dash.py\", line 1407, in dispatch\n",
      "    response.set_data(self.callback_map[output][\"callback\"](*args))\n",
      "  File \"/usr/local/anaconda/lib/python3.6/site-packages/dash/dash.py\", line 1294, in add_context\n",
      "    output_value = func(*args, **kwargs)  # %% callback invoked %%\n",
      "  File \"<ipython-input-20-660bae554010>\", line 193, in update_map\n",
      "    dl.Map(style={'width': '1000px', 'height': '500px'}, center=[dff.iloc[0,13], dff.iloc[0,14]], zoom=10, children=[\n",
      "  File \"/usr/local/anaconda/lib/python3.6/site-packages/pandas/core/indexing.py\", line 1418, in __getitem__\n",
      "    return self._getitem_tuple(key)\n",
      "  File \"/usr/local/anaconda/lib/python3.6/site-packages/pandas/core/indexing.py\", line 2092, in _getitem_tuple\n",
      "    self._has_valid_tuple(tup)\n",
      "  File \"/usr/local/anaconda/lib/python3.6/site-packages/pandas/core/indexing.py\", line 235, in _has_valid_tuple\n",
      "    self._validate_key(k, i)\n",
      "  File \"/usr/local/anaconda/lib/python3.6/site-packages/pandas/core/indexing.py\", line 2014, in _validate_key\n",
      "    self._validate_integer(key, axis)\n",
      "  File \"/usr/local/anaconda/lib/python3.6/site-packages/pandas/core/indexing.py\", line 2088, in _validate_integer\n",
      "    raise IndexError(\"single positional indexer is out-of-bounds\")\n",
      "IndexError: single positional indexer is out-of-bounds\n",
      "\n",
      "Exception on /_dash-update-component [POST]\n",
      "Traceback (most recent call last):\n",
      "  File \"/usr/local/anaconda/lib/python3.6/site-packages/pandas/core/indexes/base.py\", line 2897, in get_loc\n",
      "    return self._engine.get_loc(key)\n",
      "  File \"pandas/_libs/index.pyx\", line 107, in pandas._libs.index.IndexEngine.get_loc\n",
      "  File \"pandas/_libs/index.pyx\", line 131, in pandas._libs.index.IndexEngine.get_loc\n",
      "  File \"pandas/_libs/hashtable_class_helper.pxi\", line 1607, in pandas._libs.hashtable.PyObjectHashTable.get_item\n",
      "  File \"pandas/_libs/hashtable_class_helper.pxi\", line 1614, in pandas._libs.hashtable.PyObjectHashTable.get_item\n",
      "KeyError: 'breed'\n",
      "\n",
      "During handling of the above exception, another exception occurred:\n",
      "\n",
      "Traceback (most recent call last):\n",
      "  File \"/usr/local/anaconda/lib/python3.6/site-packages/flask/app.py\", line 2446, in wsgi_app\n",
      "    response = self.full_dispatch_request()\n",
      "  File \"/usr/local/anaconda/lib/python3.6/site-packages/flask/app.py\", line 1951, in full_dispatch_request\n",
      "    rv = self.handle_user_exception(e)\n",
      "  File \"/usr/local/anaconda/lib/python3.6/site-packages/flask/app.py\", line 1820, in handle_user_exception\n",
      "    reraise(exc_type, exc_value, tb)\n",
      "  File \"/usr/local/anaconda/lib/python3.6/site-packages/flask/_compat.py\", line 39, in reraise\n",
      "    raise value\n",
      "  File \"/usr/local/anaconda/lib/python3.6/site-packages/flask/app.py\", line 1949, in full_dispatch_request\n",
      "    rv = self.dispatch_request()\n",
      "  File \"/usr/local/anaconda/lib/python3.6/site-packages/flask/app.py\", line 1935, in dispatch_request\n",
      "    return self.view_functions[rule.endpoint](**req.view_args)\n",
      "  File \"/usr/local/anaconda/lib/python3.6/site-packages/dash/dash.py\", line 1407, in dispatch\n",
      "    response.set_data(self.callback_map[output][\"callback\"](*args))\n",
      "  File \"/usr/local/anaconda/lib/python3.6/site-packages/dash/dash.py\", line 1294, in add_context\n",
      "    output_value = func(*args, **kwargs)  # %% callback invoked %%\n",
      "  File \"<ipython-input-20-660bae554010>\", line 175, in update_graphs\n",
      "    a = dff['breed'].unique() #Have to instantiate unique breeds before sorting so pie graph values align with breed\n",
      "  File \"/usr/local/anaconda/lib/python3.6/site-packages/pandas/core/frame.py\", line 2980, in __getitem__\n",
      "    indexer = self.columns.get_loc(key)\n",
      "  File \"/usr/local/anaconda/lib/python3.6/site-packages/pandas/core/indexes/base.py\", line 2899, in get_loc\n",
      "    return self._engine.get_loc(self._maybe_cast_indexer(key))\n",
      "  File \"pandas/_libs/index.pyx\", line 107, in pandas._libs.index.IndexEngine.get_loc\n",
      "  File \"pandas/_libs/index.pyx\", line 131, in pandas._libs.index.IndexEngine.get_loc\n",
      "  File \"pandas/_libs/hashtable_class_helper.pxi\", line 1607, in pandas._libs.hashtable.PyObjectHashTable.get_item\n",
      "  File \"pandas/_libs/hashtable_class_helper.pxi\", line 1614, in pandas._libs.hashtable.PyObjectHashTable.get_item\n",
      "KeyError: 'breed'\n",
      "Exception on /_dash-update-component [POST]\n",
      "Traceback (most recent call last):\n",
      "  File \"/usr/local/anaconda/lib/python3.6/site-packages/pandas/core/indexes/base.py\", line 2897, in get_loc\n",
      "    return self._engine.get_loc(key)\n",
      "  File \"pandas/_libs/index.pyx\", line 107, in pandas._libs.index.IndexEngine.get_loc\n",
      "  File \"pandas/_libs/index.pyx\", line 131, in pandas._libs.index.IndexEngine.get_loc\n",
      "  File \"pandas/_libs/hashtable_class_helper.pxi\", line 1607, in pandas._libs.hashtable.PyObjectHashTable.get_item\n",
      "  File \"pandas/_libs/hashtable_class_helper.pxi\", line 1614, in pandas._libs.hashtable.PyObjectHashTable.get_item\n",
      "KeyError: 'breed'\n",
      "\n",
      "During handling of the above exception, another exception occurred:\n",
      "\n",
      "Traceback (most recent call last):\n",
      "  File \"/usr/local/anaconda/lib/python3.6/site-packages/flask/app.py\", line 2446, in wsgi_app\n",
      "    response = self.full_dispatch_request()\n",
      "  File \"/usr/local/anaconda/lib/python3.6/site-packages/flask/app.py\", line 1951, in full_dispatch_request\n",
      "    rv = self.handle_user_exception(e)\n",
      "  File \"/usr/local/anaconda/lib/python3.6/site-packages/flask/app.py\", line 1820, in handle_user_exception\n",
      "    reraise(exc_type, exc_value, tb)\n",
      "  File \"/usr/local/anaconda/lib/python3.6/site-packages/flask/_compat.py\", line 39, in reraise\n",
      "    raise value\n",
      "  File \"/usr/local/anaconda/lib/python3.6/site-packages/flask/app.py\", line 1949, in full_dispatch_request\n",
      "    rv = self.dispatch_request()\n",
      "  File \"/usr/local/anaconda/lib/python3.6/site-packages/flask/app.py\", line 1935, in dispatch_request\n",
      "    return self.view_functions[rule.endpoint](**req.view_args)\n",
      "  File \"/usr/local/anaconda/lib/python3.6/site-packages/dash/dash.py\", line 1407, in dispatch\n",
      "    response.set_data(self.callback_map[output][\"callback\"](*args))\n",
      "  File \"/usr/local/anaconda/lib/python3.6/site-packages/dash/dash.py\", line 1294, in add_context\n",
      "    output_value = func(*args, **kwargs)  # %% callback invoked %%\n",
      "  File \"<ipython-input-20-660bae554010>\", line 175, in update_graphs\n",
      "    a = dff['breed'].unique() #Have to instantiate unique breeds before sorting so pie graph values align with breed\n",
      "  File \"/usr/local/anaconda/lib/python3.6/site-packages/pandas/core/frame.py\", line 2980, in __getitem__\n",
      "    indexer = self.columns.get_loc(key)\n",
      "  File \"/usr/local/anaconda/lib/python3.6/site-packages/pandas/core/indexes/base.py\", line 2899, in get_loc\n",
      "    return self._engine.get_loc(self._maybe_cast_indexer(key))\n",
      "  File \"pandas/_libs/index.pyx\", line 107, in pandas._libs.index.IndexEngine.get_loc\n",
      "  File \"pandas/_libs/index.pyx\", line 131, in pandas._libs.index.IndexEngine.get_loc\n",
      "  File \"pandas/_libs/hashtable_class_helper.pxi\", line 1607, in pandas._libs.hashtable.PyObjectHashTable.get_item\n",
      "  File \"pandas/_libs/hashtable_class_helper.pxi\", line 1614, in pandas._libs.hashtable.PyObjectHashTable.get_item\n",
      "KeyError: 'breed'Exception on /_dash-update-component [POST]\n",
      "Traceback (most recent call last):\n",
      "  File \"/usr/local/anaconda/lib/python3.6/site-packages/flask/app.py\", line 2446, in wsgi_app\n",
      "    response = self.full_dispatch_request()\n",
      "  File \"/usr/local/anaconda/lib/python3.6/site-packages/flask/app.py\", line 1951, in full_dispatch_request\n",
      "    rv = self.handle_user_exception(e)\n",
      "  File \"/usr/local/anaconda/lib/python3.6/site-packages/flask/app.py\", line 1820, in handle_user_exception\n",
      "    reraise(exc_type, exc_value, tb)\n",
      "  File \"/usr/local/anaconda/lib/python3.6/site-packages/flask/_compat.py\", line 39, in reraise\n",
      "    raise value\n",
      "  File \"/usr/local/anaconda/lib/python3.6/site-packages/flask/app.py\", line 1949, in full_dispatch_request\n",
      "    rv = self.dispatch_request()\n",
      "  File \"/usr/local/anaconda/lib/python3.6/site-packages/flask/app.py\", line 1935, in dispatch_request\n",
      "    return self.view_functions[rule.endpoint](**req.view_args)\n",
      "  File \"/usr/local/anaconda/lib/python3.6/site-packages/dash/dash.py\", line 1407, in dispatch\n",
      "    response.set_data(self.callback_map[output][\"callback\"](*args))\n",
      "  File \"/usr/local/anaconda/lib/python3.6/site-packages/dash/dash.py\", line 1294, in add_context\n",
      "    output_value = func(*args, **kwargs)  # %% callback invoked %%\n",
      "  File \"<ipython-input-20-660bae554010>\", line 193, in update_map\n",
      "    dl.Map(style={'width': '1000px', 'height': '500px'}, center=[dff.iloc[0,13], dff.iloc[0,14]], zoom=10, children=[\n",
      "  File \"/usr/local/anaconda/lib/python3.6/site-packages/pandas/core/indexing.py\", line 1418, in __getitem__\n",
      "    return self._getitem_tuple(key)\n",
      "  File \"/usr/local/anaconda/lib/python3.6/site-packages/pandas/core/indexing.py\", line 2092, in _getitem_tuple\n",
      "    self._has_valid_tuple(tup)\n",
      "  File \"/usr/local/anaconda/lib/python3.6/site-packages/pandas/core/indexing.py\", line 235, in _has_valid_tuple\n",
      "    self._validate_key(k, i)\n",
      "  File \"/usr/local/anaconda/lib/python3.6/site-packages/pandas/core/indexing.py\", line 2014, in _validate_key\n",
      "    self._validate_integer(key, axis)\n",
      "  File \"/usr/local/anaconda/lib/python3.6/site-packages/pandas/core/indexing.py\", line 2088, in _validate_integer\n",
      "    raise IndexError(\"single positional indexer is out-of-bounds\")\n",
      "IndexError: single positional indexer is out-of-bounds\n"
     ]
    },
    {
     "name": "stdout",
     "output_type": "stream",
     "text": [
      "\n",
      "Exception on /_dash-update-component [POST]\n",
      "Traceback (most recent call last):\n",
      "  File \"/usr/local/anaconda/lib/python3.6/site-packages/flask/app.py\", line 2446, in wsgi_app\n",
      "    response = self.full_dispatch_request()\n",
      "  File \"/usr/local/anaconda/lib/python3.6/site-packages/flask/app.py\", line 1951, in full_dispatch_request\n",
      "    rv = self.handle_user_exception(e)\n",
      "  File \"/usr/local/anaconda/lib/python3.6/site-packages/flask/app.py\", line 1820, in handle_user_exception\n",
      "    reraise(exc_type, exc_value, tb)\n",
      "  File \"/usr/local/anaconda/lib/python3.6/site-packages/flask/_compat.py\", line 39, in reraise\n",
      "    raise value\n",
      "  File \"/usr/local/anaconda/lib/python3.6/site-packages/flask/app.py\", line 1949, in full_dispatch_request\n",
      "    rv = self.dispatch_request()\n",
      "  File \"/usr/local/anaconda/lib/python3.6/site-packages/flask/app.py\", line 1935, in dispatch_request\n",
      "    return self.view_functions[rule.endpoint](**req.view_args)\n",
      "  File \"/usr/local/anaconda/lib/python3.6/site-packages/dash/dash.py\", line 1407, in dispatch\n",
      "    response.set_data(self.callback_map[output][\"callback\"](*args))\n",
      "  File \"/usr/local/anaconda/lib/python3.6/site-packages/dash/dash.py\", line 1294, in add_context\n",
      "    output_value = func(*args, **kwargs)  # %% callback invoked %%\n",
      "  File \"<ipython-input-20-660bae554010>\", line 193, in update_map\n",
      "    dl.Map(style={'width': '1000px', 'height': '500px'}, center=[dff.iloc[0,13], dff.iloc[0,14]], zoom=10, children=[\n",
      "  File \"/usr/local/anaconda/lib/python3.6/site-packages/pandas/core/indexing.py\", line 1418, in __getitem__\n",
      "    return self._getitem_tuple(key)\n",
      "  File \"/usr/local/anaconda/lib/python3.6/site-packages/pandas/core/indexing.py\", line 2092, in _getitem_tuple\n",
      "    self._has_valid_tuple(tup)\n",
      "  File \"/usr/local/anaconda/lib/python3.6/site-packages/pandas/core/indexing.py\", line 235, in _has_valid_tuple\n",
      "    self._validate_key(k, i)\n",
      "  File \"/usr/local/anaconda/lib/python3.6/site-packages/pandas/core/indexing.py\", line 2014, in _validate_key\n",
      "    self._validate_integer(key, axis)\n",
      "  File \"/usr/local/anaconda/lib/python3.6/site-packages/pandas/core/indexing.py\", line 2088, in _validate_integer\n",
      "    raise IndexError(\"single positional indexer is out-of-bounds\")\n",
      "IndexError: single positional indexer is out-of-bounds\n",
      "Exception on /_dash-update-component [POST]\n",
      "Traceback (most recent call last):\n",
      "  File \"/usr/local/anaconda/lib/python3.6/site-packages/pandas/core/indexes/base.py\", line 2897, in get_loc\n",
      "    return self._engine.get_loc(key)\n",
      "  File \"pandas/_libs/index.pyx\", line 107, in pandas._libs.index.IndexEngine.get_loc\n",
      "  File \"pandas/_libs/index.pyx\", line 131, in pandas._libs.index.IndexEngine.get_loc\n",
      "  File \"pandas/_libs/hashtable_class_helper.pxi\", line 1607, in pandas._libs.hashtable.PyObjectHashTable.get_item\n",
      "  File \"pandas/_libs/hashtable_class_helper.pxi\", line 1614, in pandas._libs.hashtable.PyObjectHashTable.get_item\n",
      "KeyError: 'breed'\n",
      "\n",
      "During handling of the above exception, another exception occurred:\n",
      "\n",
      "Traceback (most recent call last):\n",
      "  File \"/usr/local/anaconda/lib/python3.6/site-packages/flask/app.py\", line 2446, in wsgi_app\n",
      "    response = self.full_dispatch_request()\n",
      "  File \"/usr/local/anaconda/lib/python3.6/site-packages/flask/app.py\", line 1951, in full_dispatch_request\n",
      "    rv = self.handle_user_exception(e)\n",
      "  File \"/usr/local/anaconda/lib/python3.6/site-packages/flask/app.py\", line 1820, in handle_user_exception\n",
      "    reraise(exc_type, exc_value, tb)\n",
      "  File \"/usr/local/anaconda/lib/python3.6/site-packages/flask/_compat.py\", line 39, in reraise\n",
      "    raise value\n",
      "  File \"/usr/local/anaconda/lib/python3.6/site-packages/flask/app.py\", line 1949, in full_dispatch_request\n",
      "    rv = self.dispatch_request()\n",
      "  File \"/usr/local/anaconda/lib/python3.6/site-packages/flask/app.py\", line 1935, in dispatch_request\n",
      "    return self.view_functions[rule.endpoint](**req.view_args)\n",
      "  File \"/usr/local/anaconda/lib/python3.6/site-packages/dash/dash.py\", line 1407, in dispatch\n",
      "    response.set_data(self.callback_map[output][\"callback\"](*args))\n",
      "  File \"/usr/local/anaconda/lib/python3.6/site-packages/dash/dash.py\", line 1294, in add_context\n",
      "    output_value = func(*args, **kwargs)  # %% callback invoked %%\n",
      "  File \"<ipython-input-20-660bae554010>\", line 175, in update_graphs\n",
      "    a = dff['breed'].unique() #Have to instantiate unique breeds before sorting so pie graph values align with breed\n",
      "  File \"/usr/local/anaconda/lib/python3.6/site-packages/pandas/core/frame.py\", line 2980, in __getitem__\n",
      "    indexer = self.columns.get_loc(key)\n",
      "  File \"/usr/local/anaconda/lib/python3.6/site-packages/pandas/core/indexes/base.py\", line 2899, in get_loc\n",
      "    return self._engine.get_loc(self._maybe_cast_indexer(key))\n",
      "  File \"pandas/_libs/index.pyx\", line 107, in pandas._libs.index.IndexEngine.get_loc\n",
      "  File \"pandas/_libs/index.pyx\", line 131, in pandas._libs.index.IndexEngine.get_loc\n",
      "  File \"pandas/_libs/hashtable_class_helper.pxi\", line 1607, in pandas._libs.hashtable.PyObjectHashTable.get_item\n",
      "  File \"pandas/_libs/hashtable_class_helper.pxi\", line 1614, in pandas._libs.hashtable.PyObjectHashTable.get_item\n",
      "KeyError: 'breed'\n",
      "Exception on /_dash-update-component [POST]\n",
      "Traceback (most recent call last):\n",
      "  File \"/usr/local/anaconda/lib/python3.6/site-packages/flask/app.py\", line 2446, in wsgi_app\n",
      "    response = self.full_dispatch_request()\n",
      "  File \"/usr/local/anaconda/lib/python3.6/site-packages/flask/app.py\", line 1951, in full_dispatch_request\n",
      "    rv = self.handle_user_exception(e)\n",
      "  File \"/usr/local/anaconda/lib/python3.6/site-packages/flask/app.py\", line 1820, in handle_user_exception\n",
      "    reraise(exc_type, exc_value, tb)\n",
      "  File \"/usr/local/anaconda/lib/python3.6/site-packages/flask/_compat.py\", line 39, in reraise\n",
      "    raise value\n",
      "  File \"/usr/local/anaconda/lib/python3.6/site-packages/flask/app.py\", line 1949, in full_dispatch_request\n",
      "    rv = self.dispatch_request()\n",
      "  File \"/usr/local/anaconda/lib/python3.6/site-packages/flask/app.py\", line 1935, in dispatch_request\n",
      "    return self.view_functions[rule.endpoint](**req.view_args)\n",
      "  File \"/usr/local/anaconda/lib/python3.6/site-packages/dash/dash.py\", line 1407, in dispatch\n",
      "    response.set_data(self.callback_map[output][\"callback\"](*args))\n",
      "  File \"/usr/local/anaconda/lib/python3.6/site-packages/dash/dash.py\", line 1294, in add_context\n",
      "    output_value = func(*args, **kwargs)  # %% callback invoked %%\n",
      "  File \"<ipython-input-20-660bae554010>\", line 193, in update_map\n",
      "    dl.Map(style={'width': '1000px', 'height': '500px'}, center=[dff.iloc[0,13], dff.iloc[0,14]], zoom=10, children=[\n",
      "  File \"/usr/local/anaconda/lib/python3.6/site-packages/pandas/core/indexing.py\", line 1418, in __getitem__\n",
      "    return self._getitem_tuple(key)\n",
      "  File \"/usr/local/anaconda/lib/python3.6/site-packages/pandas/core/indexing.py\", line 2092, in _getitem_tuple\n",
      "    self._has_valid_tuple(tup)\n",
      "  File \"/usr/local/anaconda/lib/python3.6/site-packages/pandas/core/indexing.py\", line 235, in _has_valid_tuple\n",
      "    self._validate_key(k, i)\n",
      "  File \"/usr/local/anaconda/lib/python3.6/site-packages/pandas/core/indexing.py\", line 2014, in _validate_key\n",
      "    self._validate_integer(key, axis)\n",
      "  File \"/usr/local/anaconda/lib/python3.6/site-packages/pandas/core/indexing.py\", line 2088, in _validate_integer\n",
      "    raise IndexError(\"single positional indexer is out-of-bounds\")\n",
      "IndexError: single positional indexer is out-of-bounds\n",
      "Exception on /_dash-update-component [POST]\n",
      "Traceback (most recent call last):\n",
      "  File \"/usr/local/anaconda/lib/python3.6/site-packages/pandas/core/indexes/base.py\", line 2897, in get_loc\n",
      "    return self._engine.get_loc(key)\n",
      "  File \"pandas/_libs/index.pyx\", line 107, in pandas._libs.index.IndexEngine.get_loc\n",
      "  File \"pandas/_libs/index.pyx\", line 131, in pandas._libs.index.IndexEngine.get_loc\n",
      "  File \"pandas/_libs/hashtable_class_helper.pxi\", line 1607, in pandas._libs.hashtable.PyObjectHashTable.get_item\n",
      "  File \"pandas/_libs/hashtable_class_helper.pxi\", line 1614, in pandas._libs.hashtable.PyObjectHashTable.get_item\n",
      "KeyError: 'breed'\n",
      "\n",
      "During handling of the above exception, another exception occurred:\n",
      "\n",
      "Traceback (most recent call last):\n",
      "  File \"/usr/local/anaconda/lib/python3.6/site-packages/flask/app.py\", line 2446, in wsgi_app\n",
      "    response = self.full_dispatch_request()\n",
      "  File \"/usr/local/anaconda/lib/python3.6/site-packages/flask/app.py\", line 1951, in full_dispatch_request\n",
      "    rv = self.handle_user_exception(e)\n",
      "  File \"/usr/local/anaconda/lib/python3.6/site-packages/flask/app.py\", line 1820, in handle_user_exception\n",
      "    reraise(exc_type, exc_value, tb)\n",
      "  File \"/usr/local/anaconda/lib/python3.6/site-packages/flask/_compat.py\", line 39, in reraise\n",
      "    raise value\n",
      "  File \"/usr/local/anaconda/lib/python3.6/site-packages/flask/app.py\", line 1949, in full_dispatch_request\n",
      "    rv = self.dispatch_request()\n",
      "  File \"/usr/local/anaconda/lib/python3.6/site-packages/flask/app.py\", line 1935, in dispatch_request\n",
      "    return self.view_functions[rule.endpoint](**req.view_args)\n",
      "  File \"/usr/local/anaconda/lib/python3.6/site-packages/dash/dash.py\", line 1407, in dispatch\n",
      "    response.set_data(self.callback_map[output][\"callback\"](*args))\n",
      "  File \"/usr/local/anaconda/lib/python3.6/site-packages/dash/dash.py\", line 1294, in add_context\n",
      "    output_value = func(*args, **kwargs)  # %% callback invoked %%\n",
      "  File \"<ipython-input-20-660bae554010>\", line 175, in update_graphs\n",
      "    a = dff['breed'].unique() #Have to instantiate unique breeds before sorting so pie graph values align with breed\n",
      "  File \"/usr/local/anaconda/lib/python3.6/site-packages/pandas/core/frame.py\", line 2980, in __getitem__\n",
      "    indexer = self.columns.get_loc(key)\n",
      "  File \"/usr/local/anaconda/lib/python3.6/site-packages/pandas/core/indexes/base.py\", line 2899, in get_loc\n",
      "    return self._engine.get_loc(self._maybe_cast_indexer(key))\n",
      "  File \"pandas/_libs/index.pyx\", line 107, in pandas._libs.index.IndexEngine.get_loc\n",
      "  File \"pandas/_libs/index.pyx\", line 131, in pandas._libs.index.IndexEngine.get_loc\n",
      "  File \"pandas/_libs/hashtable_class_helper.pxi\", line 1607, in pandas._libs.hashtable.PyObjectHashTable.get_item\n",
      "  File \"pandas/_libs/hashtable_class_helper.pxi\", line 1614, in pandas._libs.hashtable.PyObjectHashTable.get_item\n",
      "KeyError: 'breed'\n"
     ]
    },
    {
     "name": "stderr",
     "output_type": "stream",
     "text": [
      "127.0.0.1 - - [17/Oct/2022 03:28:33] \"\u001b[37mPOST /_dash-update-component HTTP/1.1\u001b[0m\" 200 -\n"
     ]
    },
    {
     "name": "stdout",
     "output_type": "stream",
     "text": [
      "Exception on /_dash-update-component [POST]\n",
      "Traceback (most recent call last):\n",
      "  File \"/usr/local/anaconda/lib/python3.6/site-packages/flask/app.py\", line 2446, in wsgi_app\n",
      "    response = self.full_dispatch_request()\n",
      "  File \"/usr/local/anaconda/lib/python3.6/site-packages/flask/app.py\", line 1951, in full_dispatch_request\n",
      "    rv = self.handle_user_exception(e)\n",
      "  File \"/usr/local/anaconda/lib/python3.6/site-packages/flask/app.py\", line 1820, in handle_user_exception\n",
      "    reraise(exc_type, exc_value, tb)\n",
      "  File \"/usr/local/anaconda/lib/python3.6/site-packages/flask/_compat.py\", line 39, in reraise\n",
      "    raise value\n",
      "  File \"/usr/local/anaconda/lib/python3.6/site-packages/flask/app.py\", line 1949, in full_dispatch_request\n",
      "    rv = self.dispatch_request()\n",
      "  File \"/usr/local/anaconda/lib/python3.6/site-packages/flask/app.py\", line 1935, in dispatch_request\n",
      "    return self.view_functions[rule.endpoint](**req.view_args)\n",
      "  File \"/usr/local/anaconda/lib/python3.6/site-packages/dash/dash.py\", line 1407, in dispatch\n",
      "    response.set_data(self.callback_map[output][\"callback\"](*args))\n",
      "  File \"/usr/local/anaconda/lib/python3.6/site-packages/dash/dash.py\", line 1294, in add_context\n",
      "    output_value = func(*args, **kwargs)  # %% callback invoked %%\n",
      "  File \"<ipython-input-20-660bae554010>\", line 193, in update_map\n",
      "    dl.Map(style={'width': '1000px', 'height': '500px'}, center=[dff.iloc[0,13], dff.iloc[0,14]], zoom=10, children=[\n",
      "  File \"/usr/local/anaconda/lib/python3.6/site-packages/pandas/core/indexing.py\", line 1418, in __getitem__\n",
      "    return self._getitem_tuple(key)\n",
      "  File \"/usr/local/anaconda/lib/python3.6/site-packages/pandas/core/indexing.py\", line 2092, in _getitem_tuple\n",
      "    self._has_valid_tuple(tup)\n",
      "  File \"/usr/local/anaconda/lib/python3.6/site-packages/pandas/core/indexing.py\", line 235, in _has_valid_tuple\n",
      "    self._validate_key(k, i)\n",
      "  File \"/usr/local/anaconda/lib/python3.6/site-packages/pandas/core/indexing.py\", line 2014, in _validate_key\n",
      "    self._validate_integer(key, axis)\n",
      "  File \"/usr/local/anaconda/lib/python3.6/site-packages/pandas/core/indexing.py\", line 2088, in _validate_integer\n",
      "    raise IndexError(\"single positional indexer is out-of-bounds\")\n",
      "IndexError: single positional indexer is out-of-bounds\n",
      "Exception on /_dash-update-component [POST]\n",
      "Traceback (most recent call last):\n",
      "  File \"/usr/local/anaconda/lib/python3.6/site-packages/pandas/core/indexes/base.py\", line 2897, in get_loc\n",
      "    return self._engine.get_loc(key)\n",
      "  File \"pandas/_libs/index.pyx\", line 107, in pandas._libs.index.IndexEngine.get_loc\n",
      "  File \"pandas/_libs/index.pyx\", line 131, in pandas._libs.index.IndexEngine.get_loc\n",
      "  File \"pandas/_libs/hashtable_class_helper.pxi\", line 1607, in pandas._libs.hashtable.PyObjectHashTable.get_item\n",
      "  File \"pandas/_libs/hashtable_class_helper.pxi\", line 1614, in pandas._libs.hashtable.PyObjectHashTable.get_item\n",
      "KeyError: 'breed'\n",
      "\n",
      "During handling of the above exception, another exception occurred:\n",
      "\n",
      "Traceback (most recent call last):\n",
      "  File \"/usr/local/anaconda/lib/python3.6/site-packages/flask/app.py\", line 2446, in wsgi_app\n",
      "    response = self.full_dispatch_request()\n",
      "  File \"/usr/local/anaconda/lib/python3.6/site-packages/flask/app.py\", line 1951, in full_dispatch_request\n",
      "    rv = self.handle_user_exception(e)\n",
      "  File \"/usr/local/anaconda/lib/python3.6/site-packages/flask/app.py\", line 1820, in handle_user_exception\n",
      "    reraise(exc_type, exc_value, tb)\n",
      "  File \"/usr/local/anaconda/lib/python3.6/site-packages/flask/_compat.py\", line 39, in reraise\n",
      "    raise value\n",
      "  File \"/usr/local/anaconda/lib/python3.6/site-packages/flask/app.py\", line 1949, in full_dispatch_request\n",
      "    rv = self.dispatch_request()\n",
      "  File \"/usr/local/anaconda/lib/python3.6/site-packages/flask/app.py\", line 1935, in dispatch_request\n",
      "    return self.view_functions[rule.endpoint](**req.view_args)\n",
      "  File \"/usr/local/anaconda/lib/python3.6/site-packages/dash/dash.py\", line 1407, in dispatch\n",
      "    response.set_data(self.callback_map[output][\"callback\"](*args))\n",
      "  File \"/usr/local/anaconda/lib/python3.6/site-packages/dash/dash.py\", line 1294, in add_context\n",
      "    output_value = func(*args, **kwargs)  # %% callback invoked %%\n",
      "  File \"<ipython-input-20-660bae554010>\", line 175, in update_graphs\n",
      "    a = dff['breed'].unique() #Have to instantiate unique breeds before sorting so pie graph values align with breed\n",
      "  File \"/usr/local/anaconda/lib/python3.6/site-packages/pandas/core/frame.py\", line 2980, in __getitem__\n",
      "    indexer = self.columns.get_loc(key)\n",
      "  File \"/usr/local/anaconda/lib/python3.6/site-packages/pandas/core/indexes/base.py\", line 2899, in get_loc\n",
      "    return self._engine.get_loc(self._maybe_cast_indexer(key))\n",
      "  File \"pandas/_libs/index.pyx\", line 107, in pandas._libs.index.IndexEngine.get_loc\n",
      "  File \"pandas/_libs/index.pyx\", line 131, in pandas._libs.index.IndexEngine.get_loc\n",
      "  File \"pandas/_libs/hashtable_class_helper.pxi\", line 1607, in pandas._libs.hashtable.PyObjectHashTable.get_item\n",
      "  File \"pandas/_libs/hashtable_class_helper.pxi\", line 1614, in pandas._libs.hashtable.PyObjectHashTable.get_item\n",
      "KeyError: 'breed'\n",
      "Exception on /_dash-update-component [POST]\n",
      "Traceback (most recent call last):\n",
      "  File \"/usr/local/anaconda/lib/python3.6/site-packages/flask/app.py\", line 2446, in wsgi_app\n",
      "    response = self.full_dispatch_request()\n",
      "  File \"/usr/local/anaconda/lib/python3.6/site-packages/flask/app.py\", line 1951, in full_dispatch_request\n",
      "    rv = self.handle_user_exception(e)\n",
      "  File \"/usr/local/anaconda/lib/python3.6/site-packages/flask/app.py\", line 1820, in handle_user_exception\n",
      "    reraise(exc_type, exc_value, tb)\n",
      "  File \"/usr/local/anaconda/lib/python3.6/site-packages/flask/_compat.py\", line 39, in reraise\n",
      "    raise value\n",
      "  File \"/usr/local/anaconda/lib/python3.6/site-packages/flask/app.py\", line 1949, in full_dispatch_request\n",
      "    rv = self.dispatch_request()\n",
      "  File \"/usr/local/anaconda/lib/python3.6/site-packages/flask/app.py\", line 1935, in dispatch_request\n",
      "    return self.view_functions[rule.endpoint](**req.view_args)\n",
      "  File \"/usr/local/anaconda/lib/python3.6/site-packages/dash/dash.py\", line 1407, in dispatch\n",
      "    response.set_data(self.callback_map[output][\"callback\"](*args))\n",
      "  File \"/usr/local/anaconda/lib/python3.6/site-packages/dash/dash.py\", line 1294, in add_context\n",
      "    output_value = func(*args, **kwargs)  # %% callback invoked %%\n",
      "  File \"<ipython-input-20-660bae554010>\", line 193, in update_map\n",
      "    dl.Map(style={'width': '1000px', 'height': '500px'}, center=[dff.iloc[0,13], dff.iloc[0,14]], zoom=10, children=[\n",
      "  File \"/usr/local/anaconda/lib/python3.6/site-packages/pandas/core/indexing.py\", line 1418, in __getitem__\n",
      "    return self._getitem_tuple(key)\n",
      "  File \"/usr/local/anaconda/lib/python3.6/site-packages/pandas/core/indexing.py\", line 2092, in _getitem_tuple\n",
      "    self._has_valid_tuple(tup)\n",
      "  File \"/usr/local/anaconda/lib/python3.6/site-packages/pandas/core/indexing.py\", line 235, in _has_valid_tuple\n",
      "    self._validate_key(k, i)\n",
      "  File \"/usr/local/anaconda/lib/python3.6/site-packages/pandas/core/indexing.py\", line 2014, in _validate_key\n",
      "    self._validate_integer(key, axis)\n",
      "  File \"/usr/local/anaconda/lib/python3.6/site-packages/pandas/core/indexing.py\", line 2088, in _validate_integer\n",
      "    raise IndexError(\"single positional indexer is out-of-bounds\")\n",
      "IndexError: single positional indexer is out-of-bounds\n",
      "Exception on /_dash-update-component [POST]\n",
      "Traceback (most recent call last):\n",
      "  File \"/usr/local/anaconda/lib/python3.6/site-packages/flask/app.py\", line 2446, in wsgi_app\n",
      "    response = self.full_dispatch_request()\n",
      "  File \"/usr/local/anaconda/lib/python3.6/site-packages/flask/app.py\", line 1951, in full_dispatch_request\n",
      "    rv = self.handle_user_exception(e)\n",
      "  File \"/usr/local/anaconda/lib/python3.6/site-packages/flask/app.py\", line 1820, in handle_user_exception\n",
      "    reraise(exc_type, exc_value, tb)\n",
      "  File \"/usr/local/anaconda/lib/python3.6/site-packages/flask/_compat.py\", line 39, in reraise\n",
      "    raise value\n",
      "  File \"/usr/local/anaconda/lib/python3.6/site-packages/flask/app.py\", line 1949, in full_dispatch_request\n",
      "    rv = self.dispatch_request()\n",
      "  File \"/usr/local/anaconda/lib/python3.6/site-packages/flask/app.py\", line 1935, in dispatch_request\n",
      "    return self.view_functions[rule.endpoint](**req.view_args)\n",
      "  File \"/usr/local/anaconda/lib/python3.6/site-packages/dash/dash.py\", line 1407, in dispatch\n",
      "    response.set_data(self.callback_map[output][\"callback\"](*args))\n",
      "  File \"/usr/local/anaconda/lib/python3.6/site-packages/dash/dash.py\", line 1294, in add_context\n",
      "    output_value = func(*args, **kwargs)  # %% callback invoked %%\n",
      "  File \"<ipython-input-20-660bae554010>\", line 193, in update_map\n",
      "    dl.Map(style={'width': '1000px', 'height': '500px'}, center=[dff.iloc[0,13], dff.iloc[0,14]], zoom=10, children=[\n",
      "  File \"/usr/local/anaconda/lib/python3.6/site-packages/pandas/core/indexing.py\", line 1418, in __getitem__\n",
      "    return self._getitem_tuple(key)\n",
      "  File \"/usr/local/anaconda/lib/python3.6/site-packages/pandas/core/indexing.py\", line 2092, in _getitem_tuple\n",
      "    self._has_valid_tuple(tup)\n",
      "  File \"/usr/local/anaconda/lib/python3.6/site-packages/pandas/core/indexing.py\", line 235, in _has_valid_tuple\n",
      "    self._validate_key(k, i)\n",
      "  File \"/usr/local/anaconda/lib/python3.6/site-packages/pandas/core/indexing.py\", line 2014, in _validate_key\n",
      "    self._validate_integer(key, axis)\n",
      "  File \"/usr/local/anaconda/lib/python3.6/site-packages/pandas/core/indexing.py\", line 2088, in _validate_integer\n",
      "    raise IndexError(\"single positional indexer is out-of-bounds\")\n",
      "IndexError: single positional indexer is out-of-bounds\n"
     ]
    },
    {
     "name": "stdout",
     "output_type": "stream",
     "text": [
      "Exception on /_dash-update-component [POST]\n",
      "Traceback (most recent call last):\n",
      "  File \"/usr/local/anaconda/lib/python3.6/site-packages/pandas/core/indexes/base.py\", line 2897, in get_loc\n",
      "    return self._engine.get_loc(key)\n",
      "  File \"pandas/_libs/index.pyx\", line 107, in pandas._libs.index.IndexEngine.get_loc\n",
      "  File \"pandas/_libs/index.pyx\", line 131, in pandas._libs.index.IndexEngine.get_loc\n",
      "  File \"pandas/_libs/hashtable_class_helper.pxi\", line 1607, in pandas._libs.hashtable.PyObjectHashTable.get_item\n",
      "  File \"pandas/_libs/hashtable_class_helper.pxi\", line 1614, in pandas._libs.hashtable.PyObjectHashTable.get_item\n",
      "KeyError: 'breed'\n",
      "\n",
      "During handling of the above exception, another exception occurred:\n",
      "\n",
      "Traceback (most recent call last):\n",
      "  File \"/usr/local/anaconda/lib/python3.6/site-packages/flask/app.py\", line 2446, in wsgi_app\n",
      "    response = self.full_dispatch_request()\n",
      "  File \"/usr/local/anaconda/lib/python3.6/site-packages/flask/app.py\", line 1951, in full_dispatch_request\n",
      "    rv = self.handle_user_exception(e)\n",
      "  File \"/usr/local/anaconda/lib/python3.6/site-packages/flask/app.py\", line 1820, in handle_user_exception\n",
      "    reraise(exc_type, exc_value, tb)\n",
      "  File \"/usr/local/anaconda/lib/python3.6/site-packages/flask/_compat.py\", line 39, in reraise\n",
      "    raise value\n",
      "  File \"/usr/local/anaconda/lib/python3.6/site-packages/flask/app.py\", line 1949, in full_dispatch_request\n",
      "    rv = self.dispatch_request()\n",
      "  File \"/usr/local/anaconda/lib/python3.6/site-packages/flask/app.py\", line 1935, in dispatch_request\n",
      "    return self.view_functions[rule.endpoint](**req.view_args)\n",
      "  File \"/usr/local/anaconda/lib/python3.6/site-packages/dash/dash.py\", line 1407, in dispatch\n",
      "    response.set_data(self.callback_map[output][\"callback\"](*args))\n",
      "  File \"/usr/local/anaconda/lib/python3.6/site-packages/dash/dash.py\", line 1294, in add_context\n",
      "    output_value = func(*args, **kwargs)  # %% callback invoked %%\n",
      "  File \"<ipython-input-20-660bae554010>\", line 175, in update_graphs\n",
      "    a = dff['breed'].unique() #Have to instantiate unique breeds before sorting so pie graph values align with breed\n",
      "  File \"/usr/local/anaconda/lib/python3.6/site-packages/pandas/core/frame.py\", line 2980, in __getitem__\n",
      "    indexer = self.columns.get_loc(key)\n",
      "  File \"/usr/local/anaconda/lib/python3.6/site-packages/pandas/core/indexes/base.py\", line 2899, in get_loc\n",
      "    return self._engine.get_loc(self._maybe_cast_indexer(key))\n",
      "  File \"pandas/_libs/index.pyx\", line 107, in pandas._libs.index.IndexEngine.get_loc\n",
      "  File \"pandas/_libs/index.pyx\", line 131, in pandas._libs.index.IndexEngine.get_loc\n",
      "  File \"pandas/_libs/hashtable_class_helper.pxi\", line 1607, in pandas._libs.hashtable.PyObjectHashTable.get_item\n",
      "  File \"pandas/_libs/hashtable_class_helper.pxi\", line 1614, in pandas._libs.hashtable.PyObjectHashTable.get_item\n",
      "KeyError: 'breed'Exception on /_dash-update-component [POST]\n",
      "Traceback (most recent call last):\n",
      "  File \"/usr/local/anaconda/lib/python3.6/site-packages/flask/app.py\", line 2446, in wsgi_app\n",
      "    response = self.full_dispatch_request()\n",
      "  File \"/usr/local/anaconda/lib/python3.6/site-packages/flask/app.py\", line 1951, in full_dispatch_request\n",
      "    rv = self.handle_user_exception(e)\n",
      "  File \"/usr/local/anaconda/lib/python3.6/site-packages/flask/app.py\", line 1820, in handle_user_exception\n",
      "    reraise(exc_type, exc_value, tb)\n",
      "  File \"/usr/local/anaconda/lib/python3.6/site-packages/flask/_compat.py\", line 39, in reraise\n",
      "    raise value\n",
      "  File \"/usr/local/anaconda/lib/python3.6/site-packages/flask/app.py\", line 1949, in full_dispatch_request\n",
      "    rv = self.dispatch_request()\n",
      "  File \"/usr/local/anaconda/lib/python3.6/site-packages/flask/app.py\", line 1935, in dispatch_request\n",
      "    return self.view_functions[rule.endpoint](**req.view_args)\n",
      "  File \"/usr/local/anaconda/lib/python3.6/site-packages/dash/dash.py\", line 1407, in dispatch\n",
      "    response.set_data(self.callback_map[output][\"callback\"](*args))\n",
      "  File \"/usr/local/anaconda/lib/python3.6/site-packages/dash/dash.py\", line 1294, in add_context\n",
      "    output_value = func(*args, **kwargs)  # %% callback invoked %%\n",
      "  File \"<ipython-input-20-660bae554010>\", line 193, in update_map\n",
      "    dl.Map(style={'width': '1000px', 'height': '500px'}, center=[dff.iloc[0,13], dff.iloc[0,14]], zoom=10, children=[\n",
      "  File \"/usr/local/anaconda/lib/python3.6/site-packages/pandas/core/indexing.py\", line 1418, in __getitem__\n",
      "    return self._getitem_tuple(key)\n",
      "  File \"/usr/local/anaconda/lib/python3.6/site-packages/pandas/core/indexing.py\", line 2092, in _getitem_tuple\n",
      "    self._has_valid_tuple(tup)\n",
      "  File \"/usr/local/anaconda/lib/python3.6/site-packages/pandas/core/indexing.py\", line 235, in _has_valid_tuple\n",
      "    self._validate_key(k, i)\n",
      "  File \"/usr/local/anaconda/lib/python3.6/site-packages/pandas/core/indexing.py\", line 2014, in _validate_key\n",
      "    self._validate_integer(key, axis)\n",
      "  File \"/usr/local/anaconda/lib/python3.6/site-packages/pandas/core/indexing.py\", line 2088, in _validate_integer\n",
      "    raise IndexError(\"single positional indexer is out-of-bounds\")\n",
      "IndexError: single positional indexer is out-of-bounds\n",
      "\n",
      "Exception on /_dash-update-component [POST]\n",
      "Traceback (most recent call last):\n",
      "  File \"/usr/local/anaconda/lib/python3.6/site-packages/flask/app.py\", line 2446, in wsgi_app\n",
      "    response = self.full_dispatch_request()\n",
      "  File \"/usr/local/anaconda/lib/python3.6/site-packages/flask/app.py\", line 1951, in full_dispatch_request\n",
      "    rv = self.handle_user_exception(e)\n",
      "  File \"/usr/local/anaconda/lib/python3.6/site-packages/flask/app.py\", line 1820, in handle_user_exception\n",
      "    reraise(exc_type, exc_value, tb)\n",
      "  File \"/usr/local/anaconda/lib/python3.6/site-packages/flask/_compat.py\", line 39, in reraise\n",
      "    raise value\n",
      "  File \"/usr/local/anaconda/lib/python3.6/site-packages/flask/app.py\", line 1949, in full_dispatch_request\n",
      "    rv = self.dispatch_request()\n",
      "  File \"/usr/local/anaconda/lib/python3.6/site-packages/flask/app.py\", line 1935, in dispatch_request\n",
      "    return self.view_functions[rule.endpoint](**req.view_args)\n",
      "  File \"/usr/local/anaconda/lib/python3.6/site-packages/dash/dash.py\", line 1407, in dispatch\n",
      "    response.set_data(self.callback_map[output][\"callback\"](*args))\n",
      "  File \"/usr/local/anaconda/lib/python3.6/site-packages/dash/dash.py\", line 1294, in add_context\n",
      "    output_value = func(*args, **kwargs)  # %% callback invoked %%\n",
      "  File \"<ipython-input-20-660bae554010>\", line 193, in update_map\n",
      "    dl.Map(style={'width': '1000px', 'height': '500px'}, center=[dff.iloc[0,13], dff.iloc[0,14]], zoom=10, children=[\n",
      "  File \"/usr/local/anaconda/lib/python3.6/site-packages/pandas/core/indexing.py\", line 1418, in __getitem__\n",
      "    return self._getitem_tuple(key)\n",
      "  File \"/usr/local/anaconda/lib/python3.6/site-packages/pandas/core/indexing.py\", line 2092, in _getitem_tuple\n",
      "    self._has_valid_tuple(tup)\n",
      "  File \"/usr/local/anaconda/lib/python3.6/site-packages/pandas/core/indexing.py\", line 235, in _has_valid_tuple\n",
      "    self._validate_key(k, i)\n",
      "  File \"/usr/local/anaconda/lib/python3.6/site-packages/pandas/core/indexing.py\", line 2014, in _validate_key\n",
      "    self._validate_integer(key, axis)\n",
      "  File \"/usr/local/anaconda/lib/python3.6/site-packages/pandas/core/indexing.py\", line 2088, in _validate_integer\n",
      "    raise IndexError(\"single positional indexer is out-of-bounds\")\n",
      "IndexError: single positional indexer is out-of-bounds\n",
      "Exception on /_dash-update-component [POST]\n",
      "Traceback (most recent call last):\n",
      "  File \"/usr/local/anaconda/lib/python3.6/site-packages/pandas/core/indexes/base.py\", line 2897, in get_loc\n",
      "    return self._engine.get_loc(key)\n",
      "  File \"pandas/_libs/index.pyx\", line 107, in pandas._libs.index.IndexEngine.get_loc\n",
      "  File \"pandas/_libs/index.pyx\", line 131, in pandas._libs.index.IndexEngine.get_loc\n",
      "  File \"pandas/_libs/hashtable_class_helper.pxi\", line 1607, in pandas._libs.hashtable.PyObjectHashTable.get_item\n",
      "  File \"pandas/_libs/hashtable_class_helper.pxi\", line 1614, in pandas._libs.hashtable.PyObjectHashTable.get_item\n",
      "KeyError: 'breed'\n",
      "\n",
      "During handling of the above exception, another exception occurred:\n",
      "\n",
      "Traceback (most recent call last):\n",
      "  File \"/usr/local/anaconda/lib/python3.6/site-packages/flask/app.py\", line 2446, in wsgi_app\n",
      "    response = self.full_dispatch_request()\n",
      "  File \"/usr/local/anaconda/lib/python3.6/site-packages/flask/app.py\", line 1951, in full_dispatch_request\n",
      "    rv = self.handle_user_exception(e)\n",
      "  File \"/usr/local/anaconda/lib/python3.6/site-packages/flask/app.py\", line 1820, in handle_user_exception\n",
      "    reraise(exc_type, exc_value, tb)\n",
      "  File \"/usr/local/anaconda/lib/python3.6/site-packages/flask/_compat.py\", line 39, in reraise\n",
      "    raise value\n",
      "  File \"/usr/local/anaconda/lib/python3.6/site-packages/flask/app.py\", line 1949, in full_dispatch_request\n",
      "    rv = self.dispatch_request()\n",
      "  File \"/usr/local/anaconda/lib/python3.6/site-packages/flask/app.py\", line 1935, in dispatch_request\n",
      "    return self.view_functions[rule.endpoint](**req.view_args)\n",
      "  File \"/usr/local/anaconda/lib/python3.6/site-packages/dash/dash.py\", line 1407, in dispatch\n",
      "    response.set_data(self.callback_map[output][\"callback\"](*args))\n",
      "  File \"/usr/local/anaconda/lib/python3.6/site-packages/dash/dash.py\", line 1294, in add_context\n",
      "    output_value = func(*args, **kwargs)  # %% callback invoked %%\n",
      "  File \"<ipython-input-20-660bae554010>\", line 175, in update_graphs\n",
      "    a = dff['breed'].unique() #Have to instantiate unique breeds before sorting so pie graph values align with breed\n",
      "  File \"/usr/local/anaconda/lib/python3.6/site-packages/pandas/core/frame.py\", line 2980, in __getitem__\n",
      "    indexer = self.columns.get_loc(key)\n",
      "  File \"/usr/local/anaconda/lib/python3.6/site-packages/pandas/core/indexes/base.py\", line 2899, in get_loc\n",
      "    return self._engine.get_loc(self._maybe_cast_indexer(key))\n",
      "  File \"pandas/_libs/index.pyx\", line 107, in pandas._libs.index.IndexEngine.get_loc\n",
      "  File \"pandas/_libs/index.pyx\", line 131, in pandas._libs.index.IndexEngine.get_loc\n",
      "  File \"pandas/_libs/hashtable_class_helper.pxi\", line 1607, in pandas._libs.hashtable.PyObjectHashTable.get_item\n",
      "  File \"pandas/_libs/hashtable_class_helper.pxi\", line 1614, in pandas._libs.hashtable.PyObjectHashTable.get_item\n",
      "KeyError: 'breed'\n"
     ]
    },
    {
     "name": "stdout",
     "output_type": "stream",
     "text": [
      "Exception on /_dash-update-component [POST]\n",
      "Traceback (most recent call last):\n",
      "  File \"/usr/local/anaconda/lib/python3.6/site-packages/flask/app.py\", line 2446, in wsgi_app\n",
      "    response = self.full_dispatch_request()\n",
      "  File \"/usr/local/anaconda/lib/python3.6/site-packages/flask/app.py\", line 1951, in full_dispatch_request\n",
      "    rv = self.handle_user_exception(e)\n",
      "  File \"/usr/local/anaconda/lib/python3.6/site-packages/flask/app.py\", line 1820, in handle_user_exception\n",
      "    reraise(exc_type, exc_value, tb)\n",
      "  File \"/usr/local/anaconda/lib/python3.6/site-packages/flask/_compat.py\", line 39, in reraise\n",
      "    raise value\n",
      "  File \"/usr/local/anaconda/lib/python3.6/site-packages/flask/app.py\", line 1949, in full_dispatch_request\n",
      "    rv = self.dispatch_request()\n",
      "  File \"/usr/local/anaconda/lib/python3.6/site-packages/flask/app.py\", line 1935, in dispatch_request\n",
      "    return self.view_functions[rule.endpoint](**req.view_args)\n",
      "  File \"/usr/local/anaconda/lib/python3.6/site-packages/dash/dash.py\", line 1407, in dispatch\n",
      "    response.set_data(self.callback_map[output][\"callback\"](*args))\n",
      "  File \"/usr/local/anaconda/lib/python3.6/site-packages/dash/dash.py\", line 1294, in add_context\n",
      "    output_value = func(*args, **kwargs)  # %% callback invoked %%\n",
      "  File \"<ipython-input-20-660bae554010>\", line 193, in update_map\n",
      "    dl.Map(style={'width': '1000px', 'height': '500px'}, center=[dff.iloc[0,13], dff.iloc[0,14]], zoom=10, children=[\n",
      "  File \"/usr/local/anaconda/lib/python3.6/site-packages/pandas/core/indexing.py\", line 1418, in __getitem__\n",
      "    return self._getitem_tuple(key)\n",
      "  File \"/usr/local/anaconda/lib/python3.6/site-packages/pandas/core/indexing.py\", line 2092, in _getitem_tuple\n",
      "    self._has_valid_tuple(tup)\n",
      "  File \"/usr/local/anaconda/lib/python3.6/site-packages/pandas/core/indexing.py\", line 235, in _has_valid_tuple\n",
      "    self._validate_key(k, i)\n",
      "  File \"/usr/local/anaconda/lib/python3.6/site-packages/pandas/core/indexing.py\", line 2014, in _validate_key\n",
      "    self._validate_integer(key, axis)\n",
      "  File \"/usr/local/anaconda/lib/python3.6/site-packages/pandas/core/indexing.py\", line 2088, in _validate_integer\n",
      "    raise IndexError(\"single positional indexer is out-of-bounds\")\n",
      "IndexError: single positional indexer is out-of-bounds\n",
      "Exception on /_dash-update-component [POST]\n",
      "Traceback (most recent call last):\n",
      "  File \"/usr/local/anaconda/lib/python3.6/site-packages/pandas/core/indexes/base.py\", line 2897, in get_loc\n",
      "    return self._engine.get_loc(key)\n",
      "  File \"pandas/_libs/index.pyx\", line 107, in pandas._libs.index.IndexEngine.get_loc\n",
      "  File \"pandas/_libs/index.pyx\", line 131, in pandas._libs.index.IndexEngine.get_loc\n",
      "  File \"pandas/_libs/hashtable_class_helper.pxi\", line 1607, in pandas._libs.hashtable.PyObjectHashTable.get_item\n",
      "  File \"pandas/_libs/hashtable_class_helper.pxi\", line 1614, in pandas._libs.hashtable.PyObjectHashTable.get_item\n",
      "KeyError: 'breed'\n",
      "\n",
      "During handling of the above exception, another exception occurred:\n",
      "\n",
      "Traceback (most recent call last):\n",
      "  File \"/usr/local/anaconda/lib/python3.6/site-packages/flask/app.py\", line 2446, in wsgi_app\n",
      "    response = self.full_dispatch_request()\n",
      "  File \"/usr/local/anaconda/lib/python3.6/site-packages/flask/app.py\", line 1951, in full_dispatch_request\n",
      "    rv = self.handle_user_exception(e)\n",
      "  File \"/usr/local/anaconda/lib/python3.6/site-packages/flask/app.py\", line 1820, in handle_user_exception\n",
      "    reraise(exc_type, exc_value, tb)\n",
      "  File \"/usr/local/anaconda/lib/python3.6/site-packages/flask/_compat.py\", line 39, in reraise\n",
      "    raise value\n",
      "  File \"/usr/local/anaconda/lib/python3.6/site-packages/flask/app.py\", line 1949, in full_dispatch_request\n",
      "    rv = self.dispatch_request()\n",
      "  File \"/usr/local/anaconda/lib/python3.6/site-packages/flask/app.py\", line 1935, in dispatch_request\n",
      "    return self.view_functions[rule.endpoint](**req.view_args)\n",
      "  File \"/usr/local/anaconda/lib/python3.6/site-packages/dash/dash.py\", line 1407, in dispatch\n",
      "    response.set_data(self.callback_map[output][\"callback\"](*args))\n",
      "  File \"/usr/local/anaconda/lib/python3.6/site-packages/dash/dash.py\", line 1294, in add_context\n",
      "    output_value = func(*args, **kwargs)  # %% callback invoked %%\n",
      "  File \"<ipython-input-20-660bae554010>\", line 175, in update_graphs\n",
      "    a = dff['breed'].unique() #Have to instantiate unique breeds before sorting so pie graph values align with breed\n",
      "  File \"/usr/local/anaconda/lib/python3.6/site-packages/pandas/core/frame.py\", line 2980, in __getitem__\n",
      "    indexer = self.columns.get_loc(key)\n",
      "  File \"/usr/local/anaconda/lib/python3.6/site-packages/pandas/core/indexes/base.py\", line 2899, in get_loc\n",
      "    return self._engine.get_loc(self._maybe_cast_indexer(key))\n",
      "  File \"pandas/_libs/index.pyx\", line 107, in pandas._libs.index.IndexEngine.get_loc\n",
      "  File \"pandas/_libs/index.pyx\", line 131, in pandas._libs.index.IndexEngine.get_loc\n",
      "  File \"pandas/_libs/hashtable_class_helper.pxi\", line 1607, in pandas._libs.hashtable.PyObjectHashTable.get_item\n",
      "  File \"pandas/_libs/hashtable_class_helper.pxi\", line 1614, in pandas._libs.hashtable.PyObjectHashTable.get_item\n",
      "KeyError: 'breed'Exception on /_dash-update-component [POST]\n",
      "Traceback (most recent call last):\n",
      "  File \"/usr/local/anaconda/lib/python3.6/site-packages/flask/app.py\", line 2446, in wsgi_app\n",
      "    response = self.full_dispatch_request()\n",
      "  File \"/usr/local/anaconda/lib/python3.6/site-packages/flask/app.py\", line 1951, in full_dispatch_request\n",
      "    rv = self.handle_user_exception(e)\n",
      "  File \"/usr/local/anaconda/lib/python3.6/site-packages/flask/app.py\", line 1820, in handle_user_exception\n",
      "    reraise(exc_type, exc_value, tb)\n",
      "  File \"/usr/local/anaconda/lib/python3.6/site-packages/flask/_compat.py\", line 39, in reraise\n",
      "    raise value\n",
      "  File \"/usr/local/anaconda/lib/python3.6/site-packages/flask/app.py\", line 1949, in full_dispatch_request\n",
      "    rv = self.dispatch_request()\n",
      "  File \"/usr/local/anaconda/lib/python3.6/site-packages/flask/app.py\", line 1935, in dispatch_request\n",
      "    return self.view_functions[rule.endpoint](**req.view_args)\n",
      "  File \"/usr/local/anaconda/lib/python3.6/site-packages/dash/dash.py\", line 1407, in dispatch\n",
      "    response.set_data(self.callback_map[output][\"callback\"](*args))\n",
      "  File \"/usr/local/anaconda/lib/python3.6/site-packages/dash/dash.py\", line 1294, in add_context\n",
      "    output_value = func(*args, **kwargs)  # %% callback invoked %%\n",
      "  File \"<ipython-input-20-660bae554010>\", line 193, in update_map\n",
      "    dl.Map(style={'width': '1000px', 'height': '500px'}, center=[dff.iloc[0,13], dff.iloc[0,14]], zoom=10, children=[\n",
      "  File \"/usr/local/anaconda/lib/python3.6/site-packages/pandas/core/indexing.py\", line 1418, in __getitem__\n",
      "    return self._getitem_tuple(key)\n",
      "  File \"/usr/local/anaconda/lib/python3.6/site-packages/pandas/core/indexing.py\", line 2092, in _getitem_tuple\n",
      "    self._has_valid_tuple(tup)\n",
      "  File \"/usr/local/anaconda/lib/python3.6/site-packages/pandas/core/indexing.py\", line 235, in _has_valid_tuple\n",
      "    self._validate_key(k, i)\n",
      "  File \"/usr/local/anaconda/lib/python3.6/site-packages/pandas/core/indexing.py\", line 2014, in _validate_key\n",
      "    self._validate_integer(key, axis)\n",
      "  File \"/usr/local/anaconda/lib/python3.6/site-packages/pandas/core/indexing.py\", line 2088, in _validate_integer\n",
      "    raise IndexError(\"single positional indexer is out-of-bounds\")\n",
      "IndexError: single positional indexer is out-of-bounds\n",
      "\n"
     ]
    },
    {
     "name": "stderr",
     "output_type": "stream",
     "text": [
      "127.0.0.1 - - [17/Oct/2022 03:28:34] \"\u001b[1m\u001b[35mPOST /_dash-update-component HTTP/1.1\u001b[0m\" 500 -\n"
     ]
    },
    {
     "name": "stdout",
     "output_type": "stream",
     "text": [
      "Exception on /_dash-update-component [POST]\n",
      "Traceback (most recent call last):\n",
      "  File \"/usr/local/anaconda/lib/python3.6/site-packages/pandas/core/indexes/base.py\", line 2897, in get_loc\n",
      "    return self._engine.get_loc(key)\n",
      "  File \"pandas/_libs/index.pyx\", line 107, in pandas._libs.index.IndexEngine.get_loc\n",
      "  File \"pandas/_libs/index.pyx\", line 131, in pandas._libs.index.IndexEngine.get_loc\n",
      "  File \"pandas/_libs/hashtable_class_helper.pxi\", line 1607, in pandas._libs.hashtable.PyObjectHashTable.get_item\n",
      "  File \"pandas/_libs/hashtable_class_helper.pxi\", line 1614, in pandas._libs.hashtable.PyObjectHashTable.get_item\n",
      "KeyError: 'breed'\n",
      "\n",
      "During handling of the above exception, another exception occurred:\n",
      "\n",
      "Traceback (most recent call last):\n",
      "  File \"/usr/local/anaconda/lib/python3.6/site-packages/flask/app.py\", line 2446, in wsgi_app\n",
      "    response = self.full_dispatch_request()\n",
      "  File \"/usr/local/anaconda/lib/python3.6/site-packages/flask/app.py\", line 1951, in full_dispatch_request\n",
      "    rv = self.handle_user_exception(e)\n",
      "  File \"/usr/local/anaconda/lib/python3.6/site-packages/flask/app.py\", line 1820, in handle_user_exception\n",
      "    reraise(exc_type, exc_value, tb)\n",
      "  File \"/usr/local/anaconda/lib/python3.6/site-packages/flask/_compat.py\", line 39, in reraise\n",
      "    raise value\n",
      "  File \"/usr/local/anaconda/lib/python3.6/site-packages/flask/app.py\", line 1949, in full_dispatch_request\n",
      "    rv = self.dispatch_request()\n",
      "  File \"/usr/local/anaconda/lib/python3.6/site-packages/flask/app.py\", line 1935, in dispatch_request\n",
      "    return self.view_functions[rule.endpoint](**req.view_args)\n",
      "  File \"/usr/local/anaconda/lib/python3.6/site-packages/dash/dash.py\", line 1407, in dispatch\n",
      "    response.set_data(self.callback_map[output][\"callback\"](*args))\n",
      "  File \"/usr/local/anaconda/lib/python3.6/site-packages/dash/dash.py\", line 1294, in add_context\n",
      "    output_value = func(*args, **kwargs)  # %% callback invoked %%\n",
      "  File \"<ipython-input-20-660bae554010>\", line 175, in update_graphs\n",
      "    a = dff['breed'].unique() #Have to instantiate unique breeds before sorting so pie graph values align with breed\n",
      "  File \"/usr/local/anaconda/lib/python3.6/site-packages/pandas/core/frame.py\", line 2980, in __getitem__\n",
      "    indexer = self.columns.get_loc(key)\n",
      "  File \"/usr/local/anaconda/lib/python3.6/site-packages/pandas/core/indexes/base.py\", line 2899, in get_loc\n",
      "    return self._engine.get_loc(self._maybe_cast_indexer(key))\n",
      "  File \"pandas/_libs/index.pyx\", line 107, in pandas._libs.index.IndexEngine.get_loc\n",
      "  File \"pandas/_libs/index.pyx\", line 131, in pandas._libs.index.IndexEngine.get_loc\n",
      "  File \"pandas/_libs/hashtable_class_helper.pxi\", line 1607, in pandas._libs.hashtable.PyObjectHashTable.get_item\n",
      "  File \"pandas/_libs/hashtable_class_helper.pxi\", line 1614, in pandas._libs.hashtable.PyObjectHashTable.get_item\n",
      "KeyError: 'breed'\n",
      "Exception on /_dash-update-component [POST]\n",
      "Traceback (most recent call last):\n",
      "  File \"/usr/local/anaconda/lib/python3.6/site-packages/pandas/core/indexes/base.py\", line 2897, in get_loc\n",
      "    return self._engine.get_loc(key)\n",
      "  File \"pandas/_libs/index.pyx\", line 107, in pandas._libs.index.IndexEngine.get_loc\n",
      "  File \"pandas/_libs/index.pyx\", line 131, in pandas._libs.index.IndexEngine.get_loc\n",
      "  File \"pandas/_libs/hashtable_class_helper.pxi\", line 1607, in pandas._libs.hashtable.PyObjectHashTable.get_item\n",
      "  File \"pandas/_libs/hashtable_class_helper.pxi\", line 1614, in pandas._libs.hashtable.PyObjectHashTable.get_item\n",
      "KeyError: 'breed'\n",
      "\n",
      "During handling of the above exception, another exception occurred:\n",
      "\n",
      "Traceback (most recent call last):\n",
      "  File \"/usr/local/anaconda/lib/python3.6/site-packages/flask/app.py\", line 2446, in wsgi_app\n",
      "    response = self.full_dispatch_request()\n",
      "  File \"/usr/local/anaconda/lib/python3.6/site-packages/flask/app.py\", line 1951, in full_dispatch_request\n",
      "    rv = self.handle_user_exception(e)\n",
      "  File \"/usr/local/anaconda/lib/python3.6/site-packages/flask/app.py\", line 1820, in handle_user_exception\n",
      "    reraise(exc_type, exc_value, tb)\n",
      "  File \"/usr/local/anaconda/lib/python3.6/site-packages/flask/_compat.py\", line 39, in reraise\n",
      "    raise value\n",
      "  File \"/usr/local/anaconda/lib/python3.6/site-packages/flask/app.py\", line 1949, in full_dispatch_request\n",
      "    rv = self.dispatch_request()\n",
      "  File \"/usr/local/anaconda/lib/python3.6/site-packages/flask/app.py\", line 1935, in dispatch_request\n",
      "    return self.view_functions[rule.endpoint](**req.view_args)\n",
      "  File \"/usr/local/anaconda/lib/python3.6/site-packages/dash/dash.py\", line 1407, in dispatch\n",
      "    response.set_data(self.callback_map[output][\"callback\"](*args))\n",
      "  File \"/usr/local/anaconda/lib/python3.6/site-packages/dash/dash.py\", line 1294, in add_context\n",
      "    output_value = func(*args, **kwargs)  # %% callback invoked %%\n",
      "  File \"<ipython-input-20-660bae554010>\", line 175, in update_graphs\n",
      "    a = dff['breed'].unique() #Have to instantiate unique breeds before sorting so pie graph values align with breed\n",
      "  File \"/usr/local/anaconda/lib/python3.6/site-packages/pandas/core/frame.py\", line 2980, in __getitem__\n",
      "    indexer = self.columns.get_loc(key)\n",
      "  File \"/usr/local/anaconda/lib/python3.6/site-packages/pandas/core/indexes/base.py\", line 2899, in get_loc\n",
      "    return self._engine.get_loc(self._maybe_cast_indexer(key))\n",
      "  File \"pandas/_libs/index.pyx\", line 107, in pandas._libs.index.IndexEngine.get_loc\n",
      "  File \"pandas/_libs/index.pyx\", line 131, in pandas._libs.index.IndexEngine.get_loc\n",
      "  File \"pandas/_libs/hashtable_class_helper.pxi\", line 1607, in pandas._libs.hashtable.PyObjectHashTable.get_item\n",
      "  File \"pandas/_libs/hashtable_class_helper.pxi\", line 1614, in pandas._libs.hashtable.PyObjectHashTable.get_item\n",
      "KeyError: 'breed'\n",
      "Exception on /_dash-update-component [POST]\n",
      "Traceback (most recent call last):\n",
      "  File \"/usr/local/anaconda/lib/python3.6/site-packages/pandas/core/indexes/base.py\", line 2897, in get_loc\n",
      "    return self._engine.get_loc(key)\n",
      "  File \"pandas/_libs/index.pyx\", line 107, in pandas._libs.index.IndexEngine.get_loc\n",
      "  File \"pandas/_libs/index.pyx\", line 131, in pandas._libs.index.IndexEngine.get_loc\n",
      "  File \"pandas/_libs/hashtable_class_helper.pxi\", line 1607, in pandas._libs.hashtable.PyObjectHashTable.get_item\n",
      "  File \"pandas/_libs/hashtable_class_helper.pxi\", line 1614, in pandas._libs.hashtable.PyObjectHashTable.get_item\n",
      "KeyError: 'breed'\n",
      "\n",
      "During handling of the above exception, another exception occurred:\n",
      "\n",
      "Traceback (most recent call last):\n",
      "  File \"/usr/local/anaconda/lib/python3.6/site-packages/flask/app.py\", line 2446, in wsgi_app\n",
      "    response = self.full_dispatch_request()\n",
      "  File \"/usr/local/anaconda/lib/python3.6/site-packages/flask/app.py\", line 1951, in full_dispatch_request\n",
      "    rv = self.handle_user_exception(e)\n",
      "  File \"/usr/local/anaconda/lib/python3.6/site-packages/flask/app.py\", line 1820, in handle_user_exception\n",
      "    reraise(exc_type, exc_value, tb)\n",
      "  File \"/usr/local/anaconda/lib/python3.6/site-packages/flask/_compat.py\", line 39, in reraise\n",
      "    raise value\n",
      "  File \"/usr/local/anaconda/lib/python3.6/site-packages/flask/app.py\", line 1949, in full_dispatch_request\n",
      "    rv = self.dispatch_request()\n",
      "  File \"/usr/local/anaconda/lib/python3.6/site-packages/flask/app.py\", line 1935, in dispatch_request\n",
      "    return self.view_functions[rule.endpoint](**req.view_args)\n",
      "  File \"/usr/local/anaconda/lib/python3.6/site-packages/dash/dash.py\", line 1407, in dispatch\n",
      "    response.set_data(self.callback_map[output][\"callback\"](*args))\n",
      "  File \"/usr/local/anaconda/lib/python3.6/site-packages/dash/dash.py\", line 1294, in add_context\n",
      "    output_value = func(*args, **kwargs)  # %% callback invoked %%\n",
      "  File \"<ipython-input-20-660bae554010>\", line 175, in update_graphs\n",
      "    a = dff['breed'].unique() #Have to instantiate unique breeds before sorting so pie graph values align with breed\n",
      "  File \"/usr/local/anaconda/lib/python3.6/site-packages/pandas/core/frame.py\", line 2980, in __getitem__\n",
      "    indexer = self.columns.get_loc(key)\n",
      "  File \"/usr/local/anaconda/lib/python3.6/site-packages/pandas/core/indexes/base.py\", line 2899, in get_loc\n",
      "    return self._engine.get_loc(self._maybe_cast_indexer(key))\n",
      "  File \"pandas/_libs/index.pyx\", line 107, in pandas._libs.index.IndexEngine.get_loc\n",
      "  File \"pandas/_libs/index.pyx\", line 131, in pandas._libs.index.IndexEngine.get_loc\n",
      "  File \"pandas/_libs/hashtable_class_helper.pxi\", line 1607, in pandas._libs.hashtable.PyObjectHashTable.get_item\n",
      "  File \"pandas/_libs/hashtable_class_helper.pxi\", line 1614, in pandas._libs.hashtable.PyObjectHashTable.get_item\n",
      "KeyError: 'breed'\n"
     ]
    },
    {
     "name": "stderr",
     "output_type": "stream",
     "text": [
      "127.0.0.1 - - [17/Oct/2022 03:28:34] \"\u001b[37mPOST /_dash-update-component HTTP/1.1\u001b[0m\" 200 -\n"
     ]
    },
    {
     "name": "stdout",
     "output_type": "stream",
     "text": [
      "Exception on /_dash-update-component [POST]\n",
      "Traceback (most recent call last):\n",
      "  File \"/usr/local/anaconda/lib/python3.6/site-packages/pandas/core/indexes/base.py\", line 2897, in get_loc\n",
      "    return self._engine.get_loc(key)\n",
      "  File \"pandas/_libs/index.pyx\", line 107, in pandas._libs.index.IndexEngine.get_loc\n",
      "  File \"pandas/_libs/index.pyx\", line 131, in pandas._libs.index.IndexEngine.get_loc\n",
      "  File \"pandas/_libs/hashtable_class_helper.pxi\", line 1607, in pandas._libs.hashtable.PyObjectHashTable.get_item\n",
      "  File \"pandas/_libs/hashtable_class_helper.pxi\", line 1614, in pandas._libs.hashtable.PyObjectHashTable.get_item\n",
      "KeyError: 'breed'\n",
      "\n",
      "During handling of the above exception, another exception occurred:\n",
      "\n",
      "Traceback (most recent call last):\n",
      "  File \"/usr/local/anaconda/lib/python3.6/site-packages/flask/app.py\", line 2446, in wsgi_app\n",
      "    response = self.full_dispatch_request()\n",
      "  File \"/usr/local/anaconda/lib/python3.6/site-packages/flask/app.py\", line 1951, in full_dispatch_request\n",
      "    rv = self.handle_user_exception(e)\n",
      "  File \"/usr/local/anaconda/lib/python3.6/site-packages/flask/app.py\", line 1820, in handle_user_exception\n",
      "    reraise(exc_type, exc_value, tb)\n",
      "  File \"/usr/local/anaconda/lib/python3.6/site-packages/flask/_compat.py\", line 39, in reraise\n",
      "    raise value\n",
      "  File \"/usr/local/anaconda/lib/python3.6/site-packages/flask/app.py\", line 1949, in full_dispatch_request\n",
      "    rv = self.dispatch_request()\n",
      "  File \"/usr/local/anaconda/lib/python3.6/site-packages/flask/app.py\", line 1935, in dispatch_request\n",
      "    return self.view_functions[rule.endpoint](**req.view_args)\n",
      "  File \"/usr/local/anaconda/lib/python3.6/site-packages/dash/dash.py\", line 1407, in dispatch\n",
      "    response.set_data(self.callback_map[output][\"callback\"](*args))\n",
      "  File \"/usr/local/anaconda/lib/python3.6/site-packages/dash/dash.py\", line 1294, in add_context\n",
      "    output_value = func(*args, **kwargs)  # %% callback invoked %%\n",
      "  File \"<ipython-input-20-660bae554010>\", line 175, in update_graphs\n",
      "    a = dff['breed'].unique() #Have to instantiate unique breeds before sorting so pie graph values align with breed\n",
      "  File \"/usr/local/anaconda/lib/python3.6/site-packages/pandas/core/frame.py\", line 2980, in __getitem__\n",
      "    indexer = self.columns.get_loc(key)\n",
      "  File \"/usr/local/anaconda/lib/python3.6/site-packages/pandas/core/indexes/base.py\", line 2899, in get_loc\n",
      "    return self._engine.get_loc(self._maybe_cast_indexer(key))\n",
      "  File \"pandas/_libs/index.pyx\", line 107, in pandas._libs.index.IndexEngine.get_loc\n",
      "  File \"pandas/_libs/index.pyx\", line 131, in pandas._libs.index.IndexEngine.get_loc\n",
      "  File \"pandas/_libs/hashtable_class_helper.pxi\", line 1607, in pandas._libs.hashtable.PyObjectHashTable.get_item\n",
      "  File \"pandas/_libs/hashtable_class_helper.pxi\", line 1614, in pandas._libs.hashtable.PyObjectHashTable.get_item\n",
      "KeyError: 'breed'\n",
      "Exception on /_dash-update-component [POST]\n",
      "Traceback (most recent call last):\n",
      "  File \"/usr/local/anaconda/lib/python3.6/site-packages/pandas/core/indexes/base.py\", line 2897, in get_loc\n",
      "    return self._engine.get_loc(key)\n",
      "  File \"pandas/_libs/index.pyx\", line 107, in pandas._libs.index.IndexEngine.get_loc\n",
      "  File \"pandas/_libs/index.pyx\", line 131, in pandas._libs.index.IndexEngine.get_loc\n",
      "  File \"pandas/_libs/hashtable_class_helper.pxi\", line 1607, in pandas._libs.hashtable.PyObjectHashTable.get_item\n",
      "  File \"pandas/_libs/hashtable_class_helper.pxi\", line 1614, in pandas._libs.hashtable.PyObjectHashTable.get_item\n",
      "KeyError: 'breed'\n",
      "\n",
      "During handling of the above exception, another exception occurred:\n",
      "\n",
      "Traceback (most recent call last):\n",
      "  File \"/usr/local/anaconda/lib/python3.6/site-packages/flask/app.py\", line 2446, in wsgi_app\n",
      "    response = self.full_dispatch_request()\n",
      "  File \"/usr/local/anaconda/lib/python3.6/site-packages/flask/app.py\", line 1951, in full_dispatch_request\n",
      "    rv = self.handle_user_exception(e)\n",
      "  File \"/usr/local/anaconda/lib/python3.6/site-packages/flask/app.py\", line 1820, in handle_user_exception\n",
      "    reraise(exc_type, exc_value, tb)\n",
      "  File \"/usr/local/anaconda/lib/python3.6/site-packages/flask/_compat.py\", line 39, in reraise\n",
      "    raise value\n",
      "  File \"/usr/local/anaconda/lib/python3.6/site-packages/flask/app.py\", line 1949, in full_dispatch_request\n",
      "    rv = self.dispatch_request()\n",
      "  File \"/usr/local/anaconda/lib/python3.6/site-packages/flask/app.py\", line 1935, in dispatch_request\n",
      "    return self.view_functions[rule.endpoint](**req.view_args)\n",
      "  File \"/usr/local/anaconda/lib/python3.6/site-packages/dash/dash.py\", line 1407, in dispatch\n",
      "    response.set_data(self.callback_map[output][\"callback\"](*args))\n",
      "  File \"/usr/local/anaconda/lib/python3.6/site-packages/dash/dash.py\", line 1294, in add_context\n",
      "    output_value = func(*args, **kwargs)  # %% callback invoked %%\n",
      "  File \"<ipython-input-20-660bae554010>\", line 175, in update_graphs\n",
      "    a = dff['breed'].unique() #Have to instantiate unique breeds before sorting so pie graph values align with breed\n",
      "  File \"/usr/local/anaconda/lib/python3.6/site-packages/pandas/core/frame.py\", line 2980, in __getitem__\n",
      "    indexer = self.columns.get_loc(key)\n",
      "  File \"/usr/local/anaconda/lib/python3.6/site-packages/pandas/core/indexes/base.py\", line 2899, in get_loc\n",
      "    return self._engine.get_loc(self._maybe_cast_indexer(key))\n",
      "  File \"pandas/_libs/index.pyx\", line 107, in pandas._libs.index.IndexEngine.get_loc\n",
      "  File \"pandas/_libs/index.pyx\", line 131, in pandas._libs.index.IndexEngine.get_loc\n",
      "  File \"pandas/_libs/hashtable_class_helper.pxi\", line 1607, in pandas._libs.hashtable.PyObjectHashTable.get_item\n",
      "  File \"pandas/_libs/hashtable_class_helper.pxi\", line 1614, in pandas._libs.hashtable.PyObjectHashTable.get_item\n",
      "KeyError: 'breed'\n",
      "Exception on /_dash-update-component [POST]\n",
      "Traceback (most recent call last):\n",
      "  File \"/usr/local/anaconda/lib/python3.6/site-packages/pandas/core/indexes/base.py\", line 2897, in get_loc\n",
      "    return self._engine.get_loc(key)\n",
      "  File \"pandas/_libs/index.pyx\", line 107, in pandas._libs.index.IndexEngine.get_loc\n",
      "  File \"pandas/_libs/index.pyx\", line 131, in pandas._libs.index.IndexEngine.get_loc\n",
      "  File \"pandas/_libs/hashtable_class_helper.pxi\", line 1607, in pandas._libs.hashtable.PyObjectHashTable.get_item\n",
      "  File \"pandas/_libs/hashtable_class_helper.pxi\", line 1614, in pandas._libs.hashtable.PyObjectHashTable.get_item\n",
      "KeyError: 'breed'\n",
      "\n",
      "During handling of the above exception, another exception occurred:\n",
      "\n",
      "Traceback (most recent call last):\n",
      "  File \"/usr/local/anaconda/lib/python3.6/site-packages/flask/app.py\", line 2446, in wsgi_app\n",
      "    response = self.full_dispatch_request()\n",
      "  File \"/usr/local/anaconda/lib/python3.6/site-packages/flask/app.py\", line 1951, in full_dispatch_request\n",
      "    rv = self.handle_user_exception(e)\n",
      "  File \"/usr/local/anaconda/lib/python3.6/site-packages/flask/app.py\", line 1820, in handle_user_exception\n",
      "    reraise(exc_type, exc_value, tb)\n",
      "  File \"/usr/local/anaconda/lib/python3.6/site-packages/flask/_compat.py\", line 39, in reraise\n",
      "    raise value\n",
      "  File \"/usr/local/anaconda/lib/python3.6/site-packages/flask/app.py\", line 1949, in full_dispatch_request\n",
      "    rv = self.dispatch_request()\n",
      "  File \"/usr/local/anaconda/lib/python3.6/site-packages/flask/app.py\", line 1935, in dispatch_request\n",
      "    return self.view_functions[rule.endpoint](**req.view_args)\n",
      "  File \"/usr/local/anaconda/lib/python3.6/site-packages/dash/dash.py\", line 1407, in dispatch\n",
      "    response.set_data(self.callback_map[output][\"callback\"](*args))\n",
      "  File \"/usr/local/anaconda/lib/python3.6/site-packages/dash/dash.py\", line 1294, in add_context\n",
      "    output_value = func(*args, **kwargs)  # %% callback invoked %%\n",
      "  File \"<ipython-input-20-660bae554010>\", line 175, in update_graphs\n",
      "    a = dff['breed'].unique() #Have to instantiate unique breeds before sorting so pie graph values align with breed\n",
      "  File \"/usr/local/anaconda/lib/python3.6/site-packages/pandas/core/frame.py\", line 2980, in __getitem__\n",
      "    indexer = self.columns.get_loc(key)\n",
      "  File \"/usr/local/anaconda/lib/python3.6/site-packages/pandas/core/indexes/base.py\", line 2899, in get_loc\n",
      "    return self._engine.get_loc(self._maybe_cast_indexer(key))\n",
      "  File \"pandas/_libs/index.pyx\", line 107, in pandas._libs.index.IndexEngine.get_loc\n",
      "  File \"pandas/_libs/index.pyx\", line 131, in pandas._libs.index.IndexEngine.get_loc\n",
      "  File \"pandas/_libs/hashtable_class_helper.pxi\", line 1607, in pandas._libs.hashtable.PyObjectHashTable.get_item\n",
      "  File \"pandas/_libs/hashtable_class_helper.pxi\", line 1614, in pandas._libs.hashtable.PyObjectHashTable.get_item\n",
      "KeyError: 'breed'\n"
     ]
    },
    {
     "name": "stdout",
     "output_type": "stream",
     "text": [
      "Exception on /_dash-update-component [POST]\n",
      "Traceback (most recent call last):\n",
      "  File \"/usr/local/anaconda/lib/python3.6/site-packages/pandas/core/indexes/base.py\", line 2897, in get_loc\n",
      "    return self._engine.get_loc(key)\n",
      "  File \"pandas/_libs/index.pyx\", line 107, in pandas._libs.index.IndexEngine.get_loc\n",
      "  File \"pandas/_libs/index.pyx\", line 131, in pandas._libs.index.IndexEngine.get_loc\n",
      "  File \"pandas/_libs/hashtable_class_helper.pxi\", line 1607, in pandas._libs.hashtable.PyObjectHashTable.get_item\n",
      "  File \"pandas/_libs/hashtable_class_helper.pxi\", line 1614, in pandas._libs.hashtable.PyObjectHashTable.get_item\n",
      "KeyError: 'breed'\n",
      "\n",
      "During handling of the above exception, another exception occurred:\n",
      "\n",
      "Traceback (most recent call last):\n",
      "  File \"/usr/local/anaconda/lib/python3.6/site-packages/flask/app.py\", line 2446, in wsgi_app\n",
      "    response = self.full_dispatch_request()\n",
      "  File \"/usr/local/anaconda/lib/python3.6/site-packages/flask/app.py\", line 1951, in full_dispatch_request\n",
      "    rv = self.handle_user_exception(e)\n",
      "  File \"/usr/local/anaconda/lib/python3.6/site-packages/flask/app.py\", line 1820, in handle_user_exception\n",
      "    reraise(exc_type, exc_value, tb)\n",
      "  File \"/usr/local/anaconda/lib/python3.6/site-packages/flask/_compat.py\", line 39, in reraise\n",
      "    raise value\n",
      "  File \"/usr/local/anaconda/lib/python3.6/site-packages/flask/app.py\", line 1949, in full_dispatch_request\n",
      "    rv = self.dispatch_request()\n",
      "  File \"/usr/local/anaconda/lib/python3.6/site-packages/flask/app.py\", line 1935, in dispatch_request\n",
      "    return self.view_functions[rule.endpoint](**req.view_args)\n",
      "  File \"/usr/local/anaconda/lib/python3.6/site-packages/dash/dash.py\", line 1407, in dispatch\n",
      "    response.set_data(self.callback_map[output][\"callback\"](*args))\n",
      "  File \"/usr/local/anaconda/lib/python3.6/site-packages/dash/dash.py\", line 1294, in add_context\n",
      "    output_value = func(*args, **kwargs)  # %% callback invoked %%\n",
      "  File \"<ipython-input-20-660bae554010>\", line 175, in update_graphs\n",
      "    a = dff['breed'].unique() #Have to instantiate unique breeds before sorting so pie graph values align with breed\n",
      "  File \"/usr/local/anaconda/lib/python3.6/site-packages/pandas/core/frame.py\", line 2980, in __getitem__\n",
      "    indexer = self.columns.get_loc(key)\n",
      "  File \"/usr/local/anaconda/lib/python3.6/site-packages/pandas/core/indexes/base.py\", line 2899, in get_loc\n",
      "    return self._engine.get_loc(self._maybe_cast_indexer(key))\n",
      "  File \"pandas/_libs/index.pyx\", line 107, in pandas._libs.index.IndexEngine.get_loc\n",
      "  File \"pandas/_libs/index.pyx\", line 131, in pandas._libs.index.IndexEngine.get_loc\n",
      "  File \"pandas/_libs/hashtable_class_helper.pxi\", line 1607, in pandas._libs.hashtable.PyObjectHashTable.get_item\n",
      "  File \"pandas/_libs/hashtable_class_helper.pxi\", line 1614, in pandas._libs.hashtable.PyObjectHashTable.get_item\n",
      "KeyError: 'breed'\n",
      "Exception on /_dash-update-component [POST]\n",
      "Traceback (most recent call last):\n",
      "  File \"/usr/local/anaconda/lib/python3.6/site-packages/pandas/core/indexes/base.py\", line 2897, in get_loc\n",
      "    return self._engine.get_loc(key)\n",
      "  File \"pandas/_libs/index.pyx\", line 107, in pandas._libs.index.IndexEngine.get_loc\n",
      "  File \"pandas/_libs/index.pyx\", line 131, in pandas._libs.index.IndexEngine.get_loc\n",
      "  File \"pandas/_libs/hashtable_class_helper.pxi\", line 1607, in pandas._libs.hashtable.PyObjectHashTable.get_item\n",
      "  File \"pandas/_libs/hashtable_class_helper.pxi\", line 1614, in pandas._libs.hashtable.PyObjectHashTable.get_item\n",
      "KeyError: 'breed'\n",
      "\n",
      "During handling of the above exception, another exception occurred:\n",
      "\n",
      "Traceback (most recent call last):\n",
      "  File \"/usr/local/anaconda/lib/python3.6/site-packages/flask/app.py\", line 2446, in wsgi_app\n",
      "    response = self.full_dispatch_request()\n",
      "  File \"/usr/local/anaconda/lib/python3.6/site-packages/flask/app.py\", line 1951, in full_dispatch_request\n",
      "    rv = self.handle_user_exception(e)\n",
      "  File \"/usr/local/anaconda/lib/python3.6/site-packages/flask/app.py\", line 1820, in handle_user_exception\n",
      "    reraise(exc_type, exc_value, tb)\n",
      "  File \"/usr/local/anaconda/lib/python3.6/site-packages/flask/_compat.py\", line 39, in reraise\n",
      "    raise value\n",
      "  File \"/usr/local/anaconda/lib/python3.6/site-packages/flask/app.py\", line 1949, in full_dispatch_request\n",
      "    rv = self.dispatch_request()\n",
      "  File \"/usr/local/anaconda/lib/python3.6/site-packages/flask/app.py\", line 1935, in dispatch_request\n",
      "    return self.view_functions[rule.endpoint](**req.view_args)\n",
      "  File \"/usr/local/anaconda/lib/python3.6/site-packages/dash/dash.py\", line 1407, in dispatch\n",
      "    response.set_data(self.callback_map[output][\"callback\"](*args))\n",
      "  File \"/usr/local/anaconda/lib/python3.6/site-packages/dash/dash.py\", line 1294, in add_context\n",
      "    output_value = func(*args, **kwargs)  # %% callback invoked %%\n",
      "  File \"<ipython-input-20-660bae554010>\", line 175, in update_graphs\n",
      "    a = dff['breed'].unique() #Have to instantiate unique breeds before sorting so pie graph values align with breed\n",
      "  File \"/usr/local/anaconda/lib/python3.6/site-packages/pandas/core/frame.py\", line 2980, in __getitem__\n",
      "    indexer = self.columns.get_loc(key)\n",
      "  File \"/usr/local/anaconda/lib/python3.6/site-packages/pandas/core/indexes/base.py\", line 2899, in get_loc\n",
      "    return self._engine.get_loc(self._maybe_cast_indexer(key))\n",
      "  File \"pandas/_libs/index.pyx\", line 107, in pandas._libs.index.IndexEngine.get_loc\n",
      "  File \"pandas/_libs/index.pyx\", line 131, in pandas._libs.index.IndexEngine.get_loc\n",
      "  File \"pandas/_libs/hashtable_class_helper.pxi\", line 1607, in pandas._libs.hashtable.PyObjectHashTable.get_item\n",
      "  File \"pandas/_libs/hashtable_class_helper.pxi\", line 1614, in pandas._libs.hashtable.PyObjectHashTable.get_item\n",
      "KeyError: 'breed'\n",
      "Exception on /_dash-update-component [POST]\n",
      "Traceback (most recent call last):\n",
      "  File \"/usr/local/anaconda/lib/python3.6/site-packages/pandas/core/indexes/base.py\", line 2897, in get_loc\n",
      "    return self._engine.get_loc(key)\n",
      "  File \"pandas/_libs/index.pyx\", line 107, in pandas._libs.index.IndexEngine.get_loc\n",
      "  File \"pandas/_libs/index.pyx\", line 131, in pandas._libs.index.IndexEngine.get_loc\n",
      "  File \"pandas/_libs/hashtable_class_helper.pxi\", line 1607, in pandas._libs.hashtable.PyObjectHashTable.get_item\n",
      "  File \"pandas/_libs/hashtable_class_helper.pxi\", line 1614, in pandas._libs.hashtable.PyObjectHashTable.get_item\n",
      "KeyError: 'breed'\n",
      "\n",
      "During handling of the above exception, another exception occurred:\n",
      "\n",
      "Traceback (most recent call last):\n",
      "  File \"/usr/local/anaconda/lib/python3.6/site-packages/flask/app.py\", line 2446, in wsgi_app\n",
      "    response = self.full_dispatch_request()\n",
      "  File \"/usr/local/anaconda/lib/python3.6/site-packages/flask/app.py\", line 1951, in full_dispatch_request\n",
      "    rv = self.handle_user_exception(e)\n",
      "  File \"/usr/local/anaconda/lib/python3.6/site-packages/flask/app.py\", line 1820, in handle_user_exception\n",
      "    reraise(exc_type, exc_value, tb)\n",
      "  File \"/usr/local/anaconda/lib/python3.6/site-packages/flask/_compat.py\", line 39, in reraise\n",
      "    raise value\n",
      "  File \"/usr/local/anaconda/lib/python3.6/site-packages/flask/app.py\", line 1949, in full_dispatch_request\n",
      "    rv = self.dispatch_request()\n",
      "  File \"/usr/local/anaconda/lib/python3.6/site-packages/flask/app.py\", line 1935, in dispatch_request\n",
      "    return self.view_functions[rule.endpoint](**req.view_args)\n",
      "  File \"/usr/local/anaconda/lib/python3.6/site-packages/dash/dash.py\", line 1407, in dispatch\n",
      "    response.set_data(self.callback_map[output][\"callback\"](*args))\n",
      "  File \"/usr/local/anaconda/lib/python3.6/site-packages/dash/dash.py\", line 1294, in add_context\n",
      "    output_value = func(*args, **kwargs)  # %% callback invoked %%\n",
      "  File \"<ipython-input-20-660bae554010>\", line 175, in update_graphs\n",
      "    a = dff['breed'].unique() #Have to instantiate unique breeds before sorting so pie graph values align with breed\n",
      "  File \"/usr/local/anaconda/lib/python3.6/site-packages/pandas/core/frame.py\", line 2980, in __getitem__\n",
      "    indexer = self.columns.get_loc(key)\n",
      "  File \"/usr/local/anaconda/lib/python3.6/site-packages/pandas/core/indexes/base.py\", line 2899, in get_loc\n",
      "    return self._engine.get_loc(self._maybe_cast_indexer(key))\n",
      "  File \"pandas/_libs/index.pyx\", line 107, in pandas._libs.index.IndexEngine.get_loc\n",
      "  File \"pandas/_libs/index.pyx\", line 131, in pandas._libs.index.IndexEngine.get_loc\n",
      "  File \"pandas/_libs/hashtable_class_helper.pxi\", line 1607, in pandas._libs.hashtable.PyObjectHashTable.get_item\n",
      "  File \"pandas/_libs/hashtable_class_helper.pxi\", line 1614, in pandas._libs.hashtable.PyObjectHashTable.get_item\n",
      "KeyError: 'breed'\n"
     ]
    },
    {
     "name": "stdout",
     "output_type": "stream",
     "text": [
      "Exception on /_dash-update-component [POST]\n",
      "Traceback (most recent call last):\n",
      "  File \"/usr/local/anaconda/lib/python3.6/site-packages/pandas/core/indexes/base.py\", line 2897, in get_loc\n",
      "    return self._engine.get_loc(key)\n",
      "  File \"pandas/_libs/index.pyx\", line 107, in pandas._libs.index.IndexEngine.get_loc\n",
      "  File \"pandas/_libs/index.pyx\", line 131, in pandas._libs.index.IndexEngine.get_loc\n",
      "  File \"pandas/_libs/hashtable_class_helper.pxi\", line 1607, in pandas._libs.hashtable.PyObjectHashTable.get_item\n",
      "  File \"pandas/_libs/hashtable_class_helper.pxi\", line 1614, in pandas._libs.hashtable.PyObjectHashTable.get_item\n",
      "KeyError: 'breed'\n",
      "\n",
      "During handling of the above exception, another exception occurred:\n",
      "\n",
      "Traceback (most recent call last):\n",
      "  File \"/usr/local/anaconda/lib/python3.6/site-packages/flask/app.py\", line 2446, in wsgi_app\n",
      "    response = self.full_dispatch_request()\n",
      "  File \"/usr/local/anaconda/lib/python3.6/site-packages/flask/app.py\", line 1951, in full_dispatch_request\n",
      "    rv = self.handle_user_exception(e)\n",
      "  File \"/usr/local/anaconda/lib/python3.6/site-packages/flask/app.py\", line 1820, in handle_user_exception\n",
      "    reraise(exc_type, exc_value, tb)\n",
      "  File \"/usr/local/anaconda/lib/python3.6/site-packages/flask/_compat.py\", line 39, in reraise\n",
      "    raise value\n",
      "  File \"/usr/local/anaconda/lib/python3.6/site-packages/flask/app.py\", line 1949, in full_dispatch_request\n",
      "    rv = self.dispatch_request()\n",
      "  File \"/usr/local/anaconda/lib/python3.6/site-packages/flask/app.py\", line 1935, in dispatch_request\n",
      "    return self.view_functions[rule.endpoint](**req.view_args)\n",
      "  File \"/usr/local/anaconda/lib/python3.6/site-packages/dash/dash.py\", line 1407, in dispatch\n",
      "    response.set_data(self.callback_map[output][\"callback\"](*args))\n",
      "  File \"/usr/local/anaconda/lib/python3.6/site-packages/dash/dash.py\", line 1294, in add_context\n",
      "    output_value = func(*args, **kwargs)  # %% callback invoked %%\n",
      "  File \"<ipython-input-20-660bae554010>\", line 175, in update_graphs\n",
      "    a = dff['breed'].unique() #Have to instantiate unique breeds before sorting so pie graph values align with breed\n",
      "  File \"/usr/local/anaconda/lib/python3.6/site-packages/pandas/core/frame.py\", line 2980, in __getitem__\n",
      "    indexer = self.columns.get_loc(key)\n",
      "  File \"/usr/local/anaconda/lib/python3.6/site-packages/pandas/core/indexes/base.py\", line 2899, in get_loc\n",
      "    return self._engine.get_loc(self._maybe_cast_indexer(key))\n",
      "  File \"pandas/_libs/index.pyx\", line 107, in pandas._libs.index.IndexEngine.get_loc\n",
      "  File \"pandas/_libs/index.pyx\", line 131, in pandas._libs.index.IndexEngine.get_loc\n",
      "  File \"pandas/_libs/hashtable_class_helper.pxi\", line 1607, in pandas._libs.hashtable.PyObjectHashTable.get_item\n",
      "  File \"pandas/_libs/hashtable_class_helper.pxi\", line 1614, in pandas._libs.hashtable.PyObjectHashTable.get_item\n",
      "KeyError: 'breed'\n"
     ]
    },
    {
     "name": "stderr",
     "output_type": "stream",
     "text": [
      "127.0.0.1 - - [17/Oct/2022 03:28:34] \"\u001b[1m\u001b[35mPOST /_dash-update-component HTTP/1.1\u001b[0m\" 500 -\n",
      "127.0.0.1 - - [17/Oct/2022 03:28:34] \"\u001b[37mPOST /_dash-update-component HTTP/1.1\u001b[0m\" 200 -\n",
      "127.0.0.1 - - [17/Oct/2022 03:28:35] \"\u001b[37mPOST /_dash-update-component HTTP/1.1\u001b[0m\" 200 -\n",
      "127.0.0.1 - - [17/Oct/2022 03:28:35] \"\u001b[37mPOST /_dash-update-component HTTP/1.1\u001b[0m\" 200 -\n",
      "127.0.0.1 - - [17/Oct/2022 03:28:43] \"\u001b[37mPOST /_dash-update-component HTTP/1.1\u001b[0m\" 200 -\n",
      "127.0.0.1 - - [17/Oct/2022 03:28:43] \"\u001b[37mPOST /_dash-update-component HTTP/1.1\u001b[0m\" 200 -\n",
      "127.0.0.1 - - [17/Oct/2022 03:29:01] \"\u001b[37mPOST /_dash-update-component HTTP/1.1\u001b[0m\" 200 -\n",
      "127.0.0.1 - - [17/Oct/2022 03:29:02] \"\u001b[37mPOST /_dash-update-component HTTP/1.1\u001b[0m\" 200 -\n"
     ]
    }
   ],
   "source": [
    "import dash\n",
    "import dash_leaflet as dl\n",
    "import dash_core_components as dcc\n",
    "import dash_html_components as html\n",
    "import plotly.express as px\n",
    "import dash_table as dt\n",
    "from dash.dependencies import Input, Output, State\n",
    "\n",
    "#import os\n",
    "#import numpy as np\n",
    "import pandas as pd\n",
    "import base64\n",
    "from pymongo import MongoClient\n",
    "from bson.json_util import dumps\n",
    "\n",
    "#### FIXED #####\n",
    "# change animal_shelter and AnimalShelter to match your CRUD Python module file name and class name\n",
    "from CRUD import AnimalShelter\n",
    "\n",
    "#import getpass to prompt for password at runtime\n",
    "from getpass import getpass\n",
    "\n",
    "###########################\n",
    "# Data Manipulation / Model\n",
    "###########################\n",
    "# FIXED: change for your username and password and CRUD Python module name\n",
    "\n",
    "username = \"aacuser\"\n",
    "#password = getpass() #Prompt for password at run time, avoid embedding passwords in code\n",
    "password = \"Example123\" #Optionally password can be hard coded, but this is a poor security practice\n",
    "database = \"AAC\"\n",
    "collection = \"animals\"\n",
    "port = \"52471\"\n",
    "shelter = AnimalShelter(username, password, port, database, collection)\n",
    "\n",
    "#Buttons list will be used for tracking filter buttons clicked\n",
    "buttons = [0, 0, 0, 0]\n",
    "\n",
    "# class read method must support return of cursor object and accept projection json input\n",
    "# Using Pandas to create a dataframe\n",
    "dd = pd.DataFrame.from_records(shelter.read())\n",
    "\n",
    "df = dd.loc[:, dd.columns != '_id'] #Remove the MongoDB unique _id column because the Dash module cannot encode it\n",
    "\n",
    "\n",
    "#########################\n",
    "# Dashboard Layout / View\n",
    "#########################\n",
    "#app = JupyterDash('Dash Datatable Only') JupyterDash was not loading in Jupyter Notebook\n",
    "app = dash.Dash('Dash Datatable') #Dash module will start the webserver on localhost:8050\n",
    "\n",
    "#FIXED Add in Grazioso Salvare’s logo\n",
    "image_filename = 'Grazioso Salvare Logo.png' # Grazioso Image\n",
    "encoded_image = base64.b64encode(open(image_filename, 'rb').read())\n",
    "\n",
    "#FIXED Place the HTML image tag in the line below into the app.layout code according to your design\n",
    "#FIXED Also remember to include a unique identifier such as your name or date\n",
    "#html.Img(src='data:image/png;base64,{}'.format(encoded_image.decode()))\n",
    "\n",
    "app.layout = html.Div([\n",
    "    html.Center(html.A( #Make the logo an html anchor that links to www.snhu.edu per customer documentation\n",
    "        [\n",
    "            html.Img(src='data:image/png;base64,{}'.format(encoded_image.decode()), style={'height':'12%','width':'12%'})\n",
    "        ], href='https://www.snhu.edu')),\n",
    "    html.Center(html.B(html.H1('Lance Cain aka robot, SNHU CS-340 Dashboard'))), #Unique tag\n",
    "    html.Hr(),\n",
    "    html.Div(  \n",
    "#FIXED Add in code for the interactive filtering options. For example, Radio buttons, drop down, checkboxes, etc.\n",
    "    className='row',\n",
    "            style={'display' : 'flex'},\n",
    "                children= [\n",
    "                    html.Button(id='submit-button-one',n_clicks=0,children='Water Rescue'),\n",
    "                    html.Button(id='submit-button-two',n_clicks=0,children='Mountain Rescue'),\n",
    "                    html.Button(id='submit-button-three',n_clicks=0,children='Disaster Rescue'),\n",
    "                    html.Button(id='submit-button-four',n_clicks=0,children='Reset Filters')\n",
    "                ]\n",
    "    ),\n",
    "    html.Hr(),\n",
    "    dt.DataTable(\n",
    "        id='datatable-id',\n",
    "        columns=[\n",
    "            {\"name\": i, \"id\": i, \"deletable\": False, \"selectable\": True} for i in df.columns\n",
    "        ],\n",
    "        data=df.to_dict('records'),\n",
    "#FIXED: Set up the features for your interactive data table to make it user-friendly for your client\n",
    "#If you completed the Module Six Assignment, you can copy in the code you created here\n",
    "        style_cell={'textAlign' : 'center', 'minWidth' : 130}, #Set a minimum width for columns to avoid cramped table defaults\n",
    "        editable=False,\n",
    "        filter_action=\"native\", #Allows filtering in the table based on matching values in each column\n",
    "        sort_action=\"native\", #Adds sorting buttons for each column, ascending or descending\n",
    "        sort_mode=\"multi\", #Allows multiple sorts with different columns\n",
    "        column_selectable=False,\n",
    "        row_selectable=False,\n",
    "        row_deletable=False,\n",
    "        selected_columns=[],\n",
    "        selected_rows=[],\n",
    "        page_action=\"native\", #Adds pagination to the table output\n",
    "        page_current= 0,\n",
    "        page_size= 10, #10 Entries per page in the table\n",
    "    ),\n",
    "    html.Br(),\n",
    "    html.Hr(),\n",
    "#This sets up the dashboard so that your chart and your geolocation chart are side-by-side\n",
    "    html.Div(className='row',\n",
    "         style={'display' : 'flex'},\n",
    "             children=[\n",
    "        html.Div(\n",
    "            id='graph-id',\n",
    "            className='col s12 m6',\n",
    "\n",
    "            ),\n",
    "        html.Div(\n",
    "            id='map-id',\n",
    "            className='col s12 m6',\n",
    "            )\n",
    "        ])\n",
    "])\n",
    "\n",
    "#############################################\n",
    "# Interaction Between Components / Controller\n",
    "#############################################\n",
    "\n",
    "\n",
    "\n",
    "#FIXED Add code to filter interactive data table with MongoDB queries\n",
    "#The following callback tracks button clicks for the four filter buttons\n",
    "#The queries for each filter scenario uses regex to search the MongoDB database for dog breeds that match certain portions of a desireable breed name since the data set uses some shorthand like \"Chesa\" in lieu of \"Chesapeake\"\n",
    "#The use of regex may result in the loss of  efficiency for specific indexes, but ensures all potential records matching for a desireable breed are included\n",
    "@app.callback(Output('datatable-id','data'), #\n",
    "              [Input('submit-button-one', 'n_clicks'), Input('submit-button-two', 'n_clicks'), Input('submit-button-three', 'n_clicks'), Input('submit-button-four', 'n_clicks'),\n",
    "    ])\n",
    "def on_click(bt1, bt2, bt3, bt4):\n",
    "    if (int(bt1)==0 and int(bt2)==0 and int(bt3)==0 and int(bt4)==0): #Return unfiltered data if nothing has been clicked\n",
    "        dd = pd.DataFrame.from_records(shelter.read())\n",
    "        df = dd.loc[:, dd.columns != '_id']\n",
    "    elif (int(bt1) > buttons[0]):\n",
    "        buttons[0] = int(bt1)\n",
    "        dd = pd.DataFrame.from_records(shelter.read({\"animal_type\" : \"Dog\", \"breed\": {\"$regex\": \"(Chesa|Newfoundland|Labrador Retriever Mix)\"}, \"sex_upon_outcome\":\"Intact Female\", \"age_upon_outcome_in_weeks\": {\"$gte\":26, \"$lte\":156}})) #Water rescue desireable breeds filtered with age\n",
    "        df = dd.loc[:, dd.columns != '_id']\n",
    "    elif (int(bt2) > buttons[1]):\n",
    "        buttons[1] = int(bt2)\n",
    "        dd = pd.DataFrame.from_records(shelter.read({\"animal_type\" : \"Dog\", \"breed\": {\"$regex\": \"(German Shepherd|Alaskan Malamute|Old English Sheepdog|Siberian Huskey|Rottweiler)\"}, \"sex_upon_outcome\":\"Intact Male\", \"age_upon_outcome_in_weeks\": {\"$gte\":26, \"$lte\":156}})) #Mountain rescue desireable breeds filtered with age\n",
    "        df = dd.loc[:, dd.columns != '_id']\n",
    "    elif (int(bt3) > buttons[2]):\n",
    "        buttons[2] = int(bt3)\n",
    "        dd = pd.DataFrame.from_records(shelter.read({\"animal_type\" : \"Dog\", \"breed\": {\"$regex\": \"(Doberman Pinscher|German Shepherd|Golden Retriever|Bloodhound|Rottweiler)\"}, \"sex_upon_outcome\":\"Intact Male\", \"age_upon_outcome_in_weeks\": {\"$gte\":20, \"$lte\":300}})) #Disaster rescue and individual tracking desireable breeds with age filter\n",
    "        df = dd.loc[:, dd.columns != '_id']\n",
    "    elif (int(bt4) > buttons[3]):\n",
    "        buttons[3] = int(bt4)\n",
    "        dd = pd.DataFrame.from_records(shelter.read()) #Fourth button resets the filter\n",
    "        df = dd.loc[:, dd.columns != '_id']\n",
    "    else:\n",
    "        dd = pd.DataFrame.from_records(shelter.read()) #Should not be encountered but if nothing else matches, reset the filter/return all data\n",
    "        df = dd.loc[:, dd.columns != '_id']\n",
    "    return df.to_dict('records')\n",
    "\n",
    "@app.callback(\n",
    "    Output('datatable-id', 'style_data_conditional'),\n",
    "    [Input('datatable-id', 'selected_columns')]\n",
    ")\n",
    "def update_styles(selected_columns):\n",
    "    return [{\n",
    "        'if': { 'column_id': i },\n",
    "        'background_color': '#D2F3FF'\n",
    "    } for i in selected_columns]\n",
    "\n",
    "@app.callback(\n",
    "    Output('graph-id', \"children\"),\n",
    "    [Input('datatable-id', \"derived_viewport_data\")])\n",
    "def update_graphs(viewData):\n",
    "    dff = pd.DataFrame.from_dict(viewData)\n",
    "    ###FIXED ####\n",
    "    # add code for chart of your choice (e.g. pie chart) \n",
    "    # Created pie chart that tracks the percentage of breeds displayed within the data table\n",
    "    # Unique breeds and values of the number shown in the table are sorted to ensure values are aligned and presented in a pie graph\n",
    "    return [\n",
    "        dcc.Graph(            \n",
    "            #figure = px.pie(dff, values=dff['breed'].value_counts(), names=dff.breed.unique(), title='Percentage of Breeds Displayed')\n",
    "            figure = px.pie(dff, values=dff['breed'].value_counts().sort_index(), names=sorted(dff['breed'].unique()), title='Percentage of Breeds Displayed')\n",
    "            \n",
    "        )    \n",
    "    ]\n",
    "\n",
    "\n",
    "#FIXED: Add in the code for your geolocation chart\n",
    "@app.callback(\n",
    "    Output('map-id', \"children\"),\n",
    "    [Input('datatable-id', \"derived_viewport_data\")])\n",
    "def update_map(viewData):\n",
    "    dff = pd.DataFrame.from_dict(viewData)\n",
    "    return [\n",
    "        #Updated example to dynamically change the map to show the location of the first animal in the table\n",
    "        dl.Map(style={'width': '1000px', 'height': '500px'}, center=[dff.iloc[0,13], dff.iloc[0,14]], zoom=10, children=[\n",
    "            dl.TileLayer(id=\"base-layer-id\"),\n",
    "            #Marker with tool tip and popup\n",
    "            dl.Marker(position=[dff.iloc[0,13],dff.iloc[0,14]], children=[\n",
    "                dl.Tooltip(dff.iloc[0,4]),\n",
    "                dl.Popup([\n",
    "                    html.H2(\"Animal Name\"),\n",
    "                    html.P(dff.iloc[0,9])\n",
    "                ])\n",
    "            ])\n",
    "        ])\n",
    "    ]\n",
    "\n",
    "\n",
    "app.run_server()"
   ]
  },
  {
   "cell_type": "code",
   "execution_count": null,
   "metadata": {},
   "outputs": [],
   "source": []
  },
  {
   "cell_type": "code",
   "execution_count": null,
   "metadata": {},
   "outputs": [],
   "source": []
  },
  {
   "cell_type": "code",
   "execution_count": null,
   "metadata": {},
   "outputs": [],
   "source": []
  }
 ],
 "metadata": {
  "kernelspec": {
   "display_name": "Python 3",
   "language": "python",
   "name": "python3"
  },
  "language_info": {
   "codemirror_mode": {
    "name": "ipython",
    "version": 3
   },
   "file_extension": ".py",
   "mimetype": "text/x-python",
   "name": "python",
   "nbconvert_exporter": "python",
   "pygments_lexer": "ipython3",
   "version": "3.6.9"
  }
 },
 "nbformat": 4,
 "nbformat_minor": 2
}
